Workbook
Name Articulo: 'Listado de Artículos'!$B:$B
Name CCCC: '[1]Listado de Artículos'!$B$1:$B$65536
Name Descripción: #REF!
Name Excel_BuiltIn__FilterDatabase: 'Listado de Artículos'!$A$9:$I$1327

Sheet Listado de Artículos
A1: COCTEL | B1: A.AAAAA
A2: COCTEL | B2: A.AAAAA
B3: A.P AJO BLANCO, CON UVA Y SARDINAS.
A4: COCTEL | B4: A.P BASE DE AJO BLANCO PRECIO KG.
A5: COCTEL | B5: A.P BOMBON DE FOIE CON CONFITURA DE TOMATE Y PAN DE PASAS.
B6: A.P BRIOX DE CURRI, SECRETO A BAJA TEMPERATURA Y CEBOLLITA ENCURTIDA. | F6: 0.63
A7: Pau gavalda. | B7: A.P BROCHETA DE GAMBA XL, CON PANKO Y CHUTNEY DE MARACUYA. | F7: 1
A8: COCTEL | B8: A.P BROCHETA DE POLLO CON SALSA KARE. | D8: M.P APERITIVOS. | F8: 0.56
A9: COCTEL | B9: A.P BUFFET DE ARROCES Y FIDEUA. | D9: M.P APERITIVOS. | F9: 1.5
A10: COCTEL | B10: A.P BUFFET DE QUESOS. | D10: M.P APERITIVOS. | F10: 1.51
A11: COCTEL | B11: A.P BUÑUELO DE BACALAO. | D11: M.P APERITIVOS. | F11: 0.58
A12: COCTEL | B12: A.P CARAMELO DE CONFIT DE PATO CON MANZANA SALTEADA Y JENJIBRE. | D12: M.P APERITIVOS. | F12: 0.7
A13: COCTEL | B13: A.P CHUPITO DE AJO BLANCO DE COCO. | D13: M.P APERITIVOS. | F13: 3.68
A14: COCTEL | B14: A.P COCA DE TOMATE SECO, PUERRO CONFITADO Y PETA CRYSPI. | D14: M.P APERITIVOS. | F14: 0.41
A15: COCTEL | B15: A.P CREMA DE AJO BLANCO, SARDINA Y UVA. | D15: M.P APERITIVOS. | F15: 0.7
A16: COCTEL | B16: A.P CROQUETA DE TXULETA, BQT CASABLANCA. | D16: M.P APERITIVOS. | F16: 0.4
A17: COCTEL | B17: A.P CUCURUCHO DE ENSALADILLA CON CAMARONES CRUJIENTES. | D17: M.P APERITIVOS. | F17: 0.42
A18: COCTEL | B18: A.P DEGUSTACION DE ARROZ NEGRO. | D18: M.P APERITIVOS. | F18: 0.8
A19: COCTEL | B19: A.P DEGUSTACION DE CROQUETAS DE SETAS Y CHULETON. | D19: M.P APERITIVOS. | F19: 0.66
B20: A.P DEGUSTACION DE FIDEOS ROSSOS. | D20: M.P APERITIVOS. | F20: 0.65
A21: COCTEL | B21: A.P DUO DE CROQUETAS. | D21: M.P APERITIVOS. | F21: 0.66
A22: COCTEL | B22: A.P ENDIVIAS CON STEAK TARTAR DE SOLOMILLO Y MOSTAZA DE CERVEZA. | D22: M.P APERITIVOS. | F22: 1.05
A23: COCTEL | B23: A.P ESPUMA DE ALLIPEBRE CON PULPO. | D23: M.P APERITIVOS. | F23: 0.78
A24: COCTEL | B24: A.P GAZPACHO DE FRAMBUESA Y BITER KAS. | D24: M.P APERITIVOS. | F24: 0.18
A25: COCTEL | B25: A.P HUMUS CON MELON, MENTA Y PLATANO MACHO. | D25: M.P APERITIVOS. | F25: 0.16
A26: COCTEL | B26: A.P JAMON AL CENTRO EVENTOS SOCIALES. | D26: M.P APERITIVOS. | F26: 1.44
A27: COCTEL | B27: A.P JAMON IBERICO AL CORTE BODAS. | D27: M.P APERITIVOS. | F27: 1.91
A28: COCTEL | B28: A.P JAMON IBERICO Y BUFET DE SURTIDO DE IBERICOS. | D28: M.P APERITIVOS. | F28: 2.82
A29: COCTEL | B29: A.P MEJILLONES MYOGA. | D29: M.P APERITIVOS. | F29: 0.38
A30: COCTEL | B30: A.P MINI BURGUER DE PAN DE SESAMO. | D30: M.P APERITIVOS. | F30: 0.68
A31: COCTEL | B31: A.P MINI GOFRE CON SOBRASADA Y MIEL. | D31: M.P APERITIVOS. | F31: 0.54
A32: COCTEL | B32: A.P NINOYAKI DE ATUN. | D32: M.P APERITIVOS. | F32: 0.6
... A35: COCTEL | B35: A.P PATATAS BRAVAS CON SALSA PICANTE, BQT CASABLANCA. | D35: M.P APERITIVOS. | F35: 0.17
A36: COCTEL | B36: A.P SALMOREJO DE SANDIA. | D36: M.P APERITIVOS.
A37: COCTEL | B37: A.P SURTIDO DE IBERICOS. | D37: M.P APERITIVOS. | F37: 0.95
A38: COCTEL | B38: A.P TARTAR DE SALMON MARINADO. | D38: M.P APERITIVOS. | F38: 0.58
A39: Sarda | B39: ACEITE DE OLIVA SUAVE 5 LT | D39: SARDA | F39: 5.95
A40: Sarda | B40: ACEITE DE OLIVA VIRGEN EXTRA SALOMO . | D40: SARDA | F40: 8.97
A41: Disbesa. | B41: aceite de trufa 250ml. 3,55€ Botella | D41: SARDA | F41: 14.22
A42: Disbesa. | B42: ACEITE GIRASOL 5 LT. | D42: SARDA | F42: 1.65
...

Sheet M.P Menú finde 45€
C3: CALÇOTADA MAS BORONAT
C4: FICHA TÉCNICA PLATO
C7: ARTÍCULO | D7: Vermouth rojo con Gilda MasBoronat
C8: TAPA | D8: ELABORADOS.
C9: unid. | D9: 1 | E9: Coste TOTAL | G9: =SUM(K12:K14) -> 1.64975 | H9: Coste KG: | J9: =G9/D9 -> 1.64975
B11: ARTICULO | C11: KG | D11: €/UN | E11: BRUTO | F11: NETO | G11: %NETO | H11: %DESP | I11: DESP | J11: SUCIO | K11: € / RACION
B12: Mirrah. rojo 15% 5 l. 15,01€ precio backin box | C12: 0.1 | D12: =IF(ISNA(VLOOKUP(B12,'Listado de Artículos'!$B$16:$F$1328,5,0)),0,(VLOOKUP(B12,'Listado de Artículos'!$B$16:$F$1328,5,0))) -> 5.62 | E12: 1 | F12: 1 | G12: =IF(E12>0,(F12/E12),"") -> 1 | H12: =IF(E12>0,(100%-G12),"") -> 0 | I12: =IF(C12>0,(H12*C12/G12),"") -> 0 | J12: =IF(C12>0,(C12+I12),"") -> 0.1 | K12: =IF(D12>0,(D12*J12),"") -> 0.562
B13: Naranja extra de mesa. | C13: 0.005 | D13: =IF(ISNA(VLOOKUP(B13,'Listado de Artículos'!$B$16:$F$1328,5,0)),0,(VLOOKUP(B13,'Listado de Artículos'!$B$16:$F$1328,5,0))) -> 17.55 | E13: 1 | F13: 1 | G13: =IF(E13>0,(F13/E13),"") -> 1 | H13: =IF(E13>0,(100%-G13),"") -> 0 | I13: =IF(C13>0,(H13*C13/G13),"") -> 0 | J13: =IF(C13>0,(C13+I13),"") -> 0.005 | K13: =IF(D13>0,(D13*J13),"") -> 0.08775
B14: Gilda MasBoronat | C14: 1 | D14: =IF(ISNA(VLOOKUP(B14,'Listado de Artículos'!$B$16:$F$1328,5,0)),0,(VLOOKUP(B14,'Listado de Artículos'!$B$16:$F$1328,5,0))) -> 1 | E14: 1 | F14: 1 | G14: =IF(E14>0,(F14/E14),"") -> 1 | H14: =IF(E14>0,(100%-G14),"") -> 0 | I14: =IF(C14>0,(H14*C14/G14),"") -> 0 | J14: =IF(C14>0,(C14+I14),"") -> 1 | K14: =IF(D14>0,(D14*J14),"") -> 1
C17: CALÇOTADA MAS BORONAT
C18: FICHA TÉCNICA PLATO
C21: ARTÍCULO | D21: Ensaladilla de gamba
C22: TAPA | D22: ELABORADOS | H22: PRECIO DE VENTA P.V.P
C23: unid. | D23: 4 | E23: Coste TOTAL | G23: =SUM(K26:K33) -> 6.8215 | H23: Coste UNID: | J23: =G23/D23 -> 1.705375
B25: ARTICULO | C25: KG | D25: €/UN | E25: BRUTO | F25: NETO | G25: %NETO | H25: %DESP | I25: DESP | J25: SUCIO | K25: € / RACION
B26: Patata Monalisa. | C26: 0.3 | D26: =IF(ISNA(VLOOKUP(B26,'Listado de Artículos'!$B$16:$F$1328,5,0)),0,(VLOOKUP(B26,'Listado de Artículos'!$B$16:$F$1328,5,0))) -> 2 | E26: 1 | F26: 1 | G26: =IF(E26>0,(F26/E26),"") -> 1 | H26: =IF(E26>0,(100%-G26),"") -> 0 | I26: =IF(C26>0,(H26*C26/G26),"") -> 0 | J26: =IF(C26>0,(C26+I26),"") -> 0.3 | K26: =IF(D26>0,(D26*J26),"") -> 0.6
B27: Mayonesa 2,2kg | C27: 0.05 | D27: =IF(ISNA(VLOOKUP(B27,'Listado de Artículos'!$B$16:$F$1328,5,0)),0,(VLOOKUP(B27,'Listado de Artículos'!$B$16:$F$1328,5,0))) -> 16.72 | E27: 1 | F27: 1 | G27: =IF(E27>0,(F27/E27),"") -> 1 | H27: =IF(E27>0,(100%-G27),"") -> 0 | I27: =IF(C27>0,(H27*C27/G27),"") -> 0 | J27: =IF(C27>0,(C27+I27),"") -> 0.05 | K27: =IF(D27>0,(D27*J27),"") -> 0.836
B28: Gamba paella | C28: 0.19 | D28: =IF(ISNA(VLOOKUP(B28,'Listado de Artículos'!$B$16:$F$1328,5,0)),0,(VLOOKUP(B28,'Listado de Artículos'!$B$16:$F$1328,5,0))) -> 10.5 | E28: 1 | F28: 1 | G28: =IF(E28>0,(F28/E28),"") -> 1 | H28: =IF(E28>0,(100%-G28),"") -> 0 | I28: =IF(C28>0,(H28*C28/G28),"") -> 0 | J28: =IF(C28>0,(C28+I28),"") -> 0.19 | K28: =IF(D28>0,(D28*J28),"") -> 1.995
B29: Limones extra. | C29: 0.1 | D29: =IF(ISNA(VLOOKUP(B29,'Listado de Artículos'!$B$16:$F$1328,5,0)),0,(VLOOKUP(B29,'Listado de Artículos'!$B$16:$F$1328,5,0))) -> 1.38 | E29: 1 | F29: 1 | G29: =IF(E29>0,(F29/E29),"") -> 1 | H29: =IF(E29>0,(100%-G29),"") -> 0 | I29: =IF(C29>0,(H29*C29/G29),"") -> 0 | J29: =IF(C29>0,(C29+I29),"") -> 0.1 | K29: =IF(D29>0,(D29*J29),"") -> 0.138
B30: Zanahorias. | C30: 0.15 | D30: =IF(ISNA(VLOOKUP(B30,'Listado de Artículos'!$B$16:$F$1328,5,0)),0,(VLOOKUP(B30,'Listado de Artículos'!$B$16:$F$1328,5,0))) -> 4.25 | E30: 1 | F30: 1 | G30: =IF(E30>0,(F30/E30),"") -> 1 | H30: =IF(E30>0,(100%-G30),"") -> 0 | I30: =IF(C30>0,(H30*C30/G30),"") -> 0 | J30: =IF(C30>0,(C30+I30),"") -> 0.15 | K30: =IF(D30>0,(D30*J30),"") -> 0.6375
B31: Huevos "L" Granja Vidal, pqt de 6 unid: 1,60€ | C31: 1 | D31: =IF(ISNA(VLOOKUP(B31,'Listado de Artículos'!$B$16:$F$1328,5,0)),0,(VLOOKUP(B31,'Listado de Artículos'!$B$16:$F$1328,5,0))) -> 0.26 | E31: 1 | F31: 1 | G31: =IF(E31>0,(F31/E31),"") -> 1 | H31: =IF(E31>0,(100%-G31),"") -> 0 | I31: =IF(C31>0,(H31*C31/G31),"") -> 0 | J31: =IF(C31>0,(C31+I31),"") -> 1 | K31: =IF(D31>0,(D31*J31),"") -> 0.26
B32: OLIVAS PARTIDAS DE LA ABUELA LATA 2,5 KG. 9,95€ | C32: 0.05 | D32: =IF(ISNA(VLOOKUP(B32,'Listado de Artículos'!$B$16:$F$1328,5,0)),0,(VLOOKUP(B32,'Listado de Artículos'!$B$16:$F$1328,5,0))) -> 13 | E32: 1 | F32: 1 | G32: =IF(E32>0,(F32/E32),"") -> 1 | H32: =IF(E32>0,(100%-G32),"") -> 0 | I32: =IF(C32>0,(H32*C32/G32),"") -> 0 | J32: =IF(C32>0,(C32+I32),"") -> 0.05 | K32: =IF(D32>0,(D32*J32),"") -> 0.65
B33: Palitos pan | C33: 0.1 | D33: =IF(ISNA(VLOOKUP(B33,'Listado de Artículos'!$B$16:$F$1328,5,0)),0,(VLOOKUP(B33,'Listado de Artículos'!$B$16:$F$1328,5,0))) -> 17.05 | E33: 1 | F33: 1 | G33: =IF(E33>0,(F33/E33),"") -> 1 | H33: =IF(E33>0,(100%-G33),"") -> 0 | I33: =IF(C33>0,(H33*C33/G33),"") -> 0 | J33: =IF(C33>0,(C33+I33),"") -> 0.1 | K33: =IF(D33>0,(D33*J33),"") -> 1.705
C36: CALÇOTADA MAS BORONAT
C37: FICHA TÉCNICA PLATO
C40: ARTÍCULO | D40: Tartar de fuet con encurtidos
C41: TAPA | D41: ELABORADOS.
C42: unid. | D42: 4 | E42: Coste TOTAL | G42: =SUM(K45:K50) -> 5.18275 | H42: Coste UNID: | J42: =G42/D42 -> 1.2956875
B44: ARTICULO | C44: KG | D44: €/UN | E44: BRUTO | F44: NETO | G44: %NETO | H44: %DESP | I44: DESP | J44: SUCIO | K44: € / RACION
B45: Fuet tradicional precio kg* calçotada. | C45: 0.1 | D45: =IF(ISNA(VLOOKUP(B45,'Listado de Artículos'!$B$16:$F$1328,5,0)),0,(VLOOKUP(B45,'Listado de Artículos'!$B$16:$F$1328,5,0))) -> 11.5 | E45: 1 | F45: 1 | G45: =IF(E45>0,(F45/E45),"") -> 1 | H45: =IF(E45>0,(100%-G45),"") -> 0 | I45: =IF(C45>0,(H45*C45/G45),"") -> 0 | J45: =IF(C45>0,(C45+I45),"") -> 0.1 | K45: =IF(D45>0,(D45*J45),"") -> 1.15
B46: Encurtidos tartar | C46: 1 | D46: =IF(ISNA(VLOOKUP(B46,'Listado de Artículos'!$B$16:$F$1328,5,0)),0,(VLOOKUP(B46,'Listado de Artículos'!$B$16:$F$1328,5,0))) -> 0.2 | E46: 1 | F46: 1 | G46: =IF(E46>0,(F46/E46),"") -> 1 | H46: =IF(E46>0,(100%-G46),"") -> 0 | I46: =IF(C46>0,(H46*C46/G46),"") -> 0 | J46: =IF(C46>0,(C46+I46),"") -> 1 | K46: =IF(D46>0,(D46*J46),"") -> 0.2
B47: Huevos "L" Granja Vidal, pqt de 6 unid: 1,60€ | C47: 1 | D47: =IF(ISNA(VLOOKUP(B47,'Listado de Artículos'!$B$16:$F$1328,5,0)),0,(VLOOKUP(B47,'Listado de Artículos'!$B$16:$F$1328,5,0))) -> 0.26 | E47: 1 | F47: 1 | G47: =IF(E47>0,(F47/E47),"") -> 1 | H47: =IF(E47>0,(100%-G47),"") -> 0 | I47: =IF(C47>0,(H47*C47/G47),"") -> 0 | J47: =IF(C47>0,(C47+I47),"") -> 1 | K47: =IF(D47>0,(D47*J47),"") -> 0.26
B48: ACEITE DE OLIVA VIRGEN EXTRA SALOMO . | C48: 0.075 | D48: =IF(ISNA(VLOOKUP(B48,'Listado de Artículos'!$B$16:$F$1328,5,0)),0,(VLOOKUP(B48,'Listado de Artículos'!$B$16:$F$1328,5,0))) -> 8.97 | E48: 1 | F48: 1 | G48: =IF(E48>0,(F48/E48),"") -> 1 | H48: =IF(E48>0,(100%-G48),"") -> 0 | I48: =IF(C48>0,(H48*C48/G48),"") -> 0 | J48: =IF(C48>0,(C48+I48),"") -> 0.075 | K48: =IF(D48>0,(D48*J48),"") -> 0.67275
B49: Pan cristal precortado. (3,200 gr). 64 *50. 26,78€ Caja. 0,20€ medio trozo. | C49: 1 | D49: =IF(ISNA(VLOOKUP(B49,'Listado de Artículos'!$B$16:$F$1328,5,0)),0,(VLOOKUP(B49,'Listado de Artículos'!$B$16:$F$1328,5,0))) -> 2.9 | E49: 1 | F49: 1 | G49: =IF(E49>0,(F49/E49),"") -> 1 | H49: =IF(E49>0,(100%-G49),"") -> 0 | I49: =IF(C49>0,(H49*C49/G49),"") -> 0 | J49: =IF(C49>0,(C49+I49),"") -> 1 | K49: =IF(D49>0,(D49*J49),"") -> 2.9
C53: CALÇOTADA MAS BORONAT
C54: FICHA TÉCNICA PLATO
C57: ARTÍCULO | D57: Calçot en tempura y salsa romesco
C58: TAPA | D58: ELABORADOS.
C59: unid. | D59: 4 | E59: Coste TOTAL | G59: =SUM(K62:K67) -> 2.1878 | H59: PAX | J59: =G59/D59 -> 0.54695
B61: ARTICULO | C61: KG | D61: €/UN | E61: BRUTO | F61: NETO | G61: %NETO | H61: %DESP | I61: DESP | J61: SUCIO | K61: € / RACION
...

Sheet Menú bbq finde 45€
A2: MENU BBQ FIN DE SEMANA 45€ CARTA. 01/04/2026
A4: APERITIVO. | B4: P.V.P | C4: NETO | D4: COSTO | E4: FOOD COST
A5: CALÇOTADA. APERITIVO CARTA | B5: GR O KG. | C5: PRECIO KG | D5: EUROS/RACION.
A6: Vermuth rojo con Gilda MasBoronat | B6: 1 | C6: =IF(ISNA(VLOOKUP(A6,'Listado de Artículos'!$B$16:$F$1328,5,0)),0,(VLOOKUP(A6,'Listado de Artículos'!$B$16:$F$1328,5,0))) -> 1.64975 | D6: =B6*C6 -> 1.64975
A7: Ensaladilla de Gamba | B7: 1 | C7: =IF(ISNA(VLOOKUP(A7,'Listado de Artículos'!$B$16:$F$1328,5,0)),0,(VLOOKUP(A7,'Listado de Artículos'!$B$16:$F$1328,5,0))) -> 1.705375 | D7: =B7*C7 -> 1.705375
A8: Tartar de fuet | B8: 1 | C8: =IF(ISNA(VLOOKUP(A8,'Listado de Artículos'!$B$16:$F$1328,5,0)),0,(VLOOKUP(A8,'Listado de Artículos'!$B$16:$F$1328,5,0))) -> 1.2956875 | D8: =B8*C8 -> 1.2956875
A9: Calçots en tempura!!! | B9: 1 | C9: =IF(ISNA(VLOOKUP(A9,'Listado de Artículos'!$B$16:$F$1328,5,0)),0,(VLOOKUP(A9,'Listado de Artículos'!$B$16:$F$1328,5,0))) -> 0.54695 | D9: =B9*C9 -> 0.54695
A10: EN MESA.
A11: Ensalada para calçotada terminada lechuga de pages. | B11: 1 | C11: =IF(ISNA(VLOOKUP(A11,'Listado de Artículos'!$B$16:$F$1328,5,0)),0,(VLOOKUP(A11,'Listado de Artículos'!$B$16:$F$1328,5,0))) -> 0.7 | D11: =B11*C11 -> 0.7
A12: MENU CALÇOTADA. CESTA DE PAN, TOMATE Y AJO. | B12: 1 | C12: =IF(ISNA(VLOOKUP(A12,'Listado de Artículos'!$B$16:$F$1328,5,0)),0,(VLOOKUP(A12,'Listado de Artículos'!$B$16:$F$1328,5,0))) -> 0.54 | D12: =B12*C12 -> 0.54
A13: Parrillada bbq fin de semana | B13: 1 | C13: =IF(ISNA(VLOOKUP(A13,'Listado de Artículos'!$B$16:$F$1328,5,0)),0,(VLOOKUP(A13,'Listado de Artículos'!$B$16:$F$1328,5,0))) -> 5.42026 | D13: =B13*C13 -> 5.42026
A14: Salsa Allioli. natural. bote de 1 lt. | B14: 0.03 | C14: =IF(ISNA(VLOOKUP(A14,'Listado de Artículos'!$B$16:$F$1328,5,0)),0,(VLOOKUP(A14,'Listado de Artículos'!$B$16:$F$1328,5,0))) -> 3.85 | D14: =B14*C14 -> 0.1155
A15: POSTRES
A16: Crema Catalana. | B16: 1 | C16: =IF(ISNA(VLOOKUP(A16,'Listado de Artículos'!$B$16:$F$1328,5,0)),0,(VLOOKUP(A16,'Listado de Artículos'!$B$16:$F$1328,5,0))) -> 0.5 | D16: =B16*C16 -> 0.5
A18: POSTRES
A19: CLOS PINELL TERRA TINTO ALTA | B19: 0.25 | C19: =IF(ISNA(VLOOKUP(A19,'Listado de Artículos'!$B$16:$F$1328,5,0)),0,(VLOOKUP(A19,'Listado de Artículos'!$B$16:$F$1328,5,0))) -> 0.9 | D19: =B19*C19 -> 0.225
A20: Agua Fon vella 1 LT Caja de 12 unid. | B20: 0.5 | C20: =IF(ISNA(VLOOKUP(A20,'Listado de Artículos'!$B$16:$F$1328,5,0)),0,(VLOOKUP(A20,'Listado de Artículos'!$B$16:$F$1328,5,0))) -> 0.8 | D20: =B20*C20 -> 0.4
A21: Cafe Natural. 1 kg. 120 cafes. 24,48€ .kg. 0,22 unid | B21: 1 | C21: =IF(ISNA(VLOOKUP(A21,'Listado de Artículos'!$B$16:$F$1328,5,0)),0,(VLOOKUP(A21,'Listado de Artículos'!$B$16:$F$1328,5,0))) -> 0.65 | D21: =B21*C21 -> 0.65
B22: 0.3 | C22: =IF(ISNA(VLOOKUP(A22,'Listado de Artículos'!$B$16:$F$1328,5,0)),0,(VLOOKUP(A22,'Listado de Artículos'!$B$16:$F$1328,5,0))) -> 0 | D22: =B22*C22 -> 0
A24: ESCANDALLO | B24: 46 | C24: =B24/1.1 -> 41.818182 | D24: =SUM(D6:D23) -> 13.748523 | E24: =(D24*100/C24)/100 -> 0.32876902

Sheet Menú paella finde 45€
A2: MENU BBQ 45€ CARTA. 01/04/2026
A4: APERITIVO. | B4: P.V.P | C4: NETO | D4: COSTO | E4: FOOD COST
A5: CALÇOTADA. APERITIVO CARTA | B5: GR O KG. | C5: PRECIO KG | D5: EUROS/RACION.
A6: Vermuth rojo con Gilda MasBoronat | B6: 1 | C6: =IF(ISNA(VLOOKUP(A6,'Listado de Artículos'!$B$16:$F$1328,5,0)),0,(VLOOKUP(A6,'Listado de Artículos'!$B$16:$F$1328,5,0))) -> 1.64975 | D6: =B6*C6 -> 1.64975
A7: Ensaladilla de Gamba | B7: 1 | C7: =IF(ISNA(VLOOKUP(A7,'Listado de Artículos'!$B$16:$F$1328,5,0)),0,(VLOOKUP(A7,'Listado de Artículos'!$B$16:$F$1328,5,0))) -> 1.705375 | D7: =B7*C7 -> 1.705375
A8: Tartar de fuet | B8: 1 | C8: =IF(ISNA(VLOOKUP(A8,'Listado de Artículos'!$B$16:$F$1328,5,0)),0,(VLOOKUP(A8,'Listado de Artículos'!$B$16:$F$1328,5,0))) -> 1.2956875 | D8: =B8*C8 -> 1.2956875
A9: Calçots en tempura!!! | B9: 1 | C9: =IF(ISNA(VLOOKUP(A9,'Listado de Artículos'!$B$16:$F$1328,5,0)),0,(VLOOKUP(A9,'Listado de Artículos'!$B$16:$F$1328,5,0))) -> 0.54695 | D9: =B9*C9 -> 0.54695
A10: EN MESA.
A11: Ensalada para calçotada terminada lechuga de pages. | B11: 1 | C11: =IF(ISNA(VLOOKUP(A11,'Listado de Artículos'!$B$16:$F$1328,5,0)),0,(VLOOKUP(A11,'Listado de Artículos'!$B$16:$F$1328,5,0))) -> 0.7 | D11: =B11*C11 -> 0.7
A12: MENU CALÇOTADA. CESTA DE PAN, TOMATE Y AJO. | B12: 1 | C12: =IF(ISNA(VLOOKUP(A12,'Listado de Artículos'!$B$16:$F$1328,5,0)),0,(VLOOKUP(A12,'Listado de Artículos'!$B$16:$F$1328,5,0))) -> 0.54 | D12: =B12*C12 -> 0.54
B13: 1 | C13: =IF(ISNA(VLOOKUP(A13,'Listado de Artículos'!$B$16:$F$1328,5,0)),0,(VLOOKUP(A13,'Listado de Artículos'!$B$16:$F$1328,5,0))) -> 0 | D13: 5.95
A14: Salsa Allioli. natural. bote de 1 lt. | B14: 0.03 | C14: =IF(ISNA(VLOOKUP(A14,'Listado de Artículos'!$B$16:$F$1328,5,0)),0,(VLOOKUP(A14,'Listado de Artículos'!$B$16:$F$1328,5,0))) -> 3.85 | D14: =B14*C14 -> 0.1155
A15: POSTRES
A16: Crema Catalana. | B16: 1 | C16: =IF(ISNA(VLOOKUP(A16,'Listado de Artículos'!$B$16:$F$1328,5,0)),0,(VLOOKUP(A16,'Listado de Artículos'!$B$16:$F$1328,5,0))) -> 0.5 | D16: =B16*C16 -> 0.5
A17: MENU CALÇOTADA NARANJA CON MIEL. POR PAX. | B17: 1 | C17: =IF(ISNA(VLOOKUP(A17,'Listado de Artículos'!$B$16:$F$1328,5,0)),0,(VLOOKUP(A17,'Listado de Artículos'!$B$16:$F$1328,5,0))) -> 0.37 | D17: =B17*C17 -> 0.37
A18: POSTRES
A19: CLOS PINELL TERRA TINTO ALTA | B19: 0.25 | C19: =IF(ISNA(VLOOKUP(A19,'Listado de Artículos'!$B$16:$F$1328,5,0)),0,(VLOOKUP(A19,'Listado de Artículos'!$B$16:$F$1328,5,0))) -> 0.9 | D19: =B19*C19 -> 0.225
B20: 0.15 | C20: =IF(ISNA(VLOOKUP(A20,'Listado de Artículos'!$B$16:$F$1328,5,0)),0,(VLOOKUP(A20,'Listado de Artículos'!$B$16:$F$1328,5,0))) -> 0 | D20: =B20*C20 -> 0
A21: Cafe Natural. 1 kg. 120 cafes. 24,48€ .kg. 0,22 unid | B21: 1 | C21: =IF(ISNA(VLOOKUP(A21,'Listado de Artículos'!$B$16:$F$1328,5,0)),0,(VLOOKUP(A21,'Listado de Artículos'!$B$16:$F$1328,5,0))) -> 0.65 | D21: =B21*C21 -> 0.65
B22: 0.3 | C22: =IF(ISNA(VLOOKUP(A22,'Listado de Artículos'!$B$16:$F$1328,5,0)),0,(VLOOKUP(A22,'Listado de Artículos'!$B$16:$F$1328,5,0))) -> 0 | D22: =B22*C22 -> 0
A24: ESCANDALLO | B24: 46 | C24: =B24/1.1 -> 41.818182 | D24: =SUM(D6:D23) -> 14.248263 | E24: =(D24*100/C24)/100 -> 0.34071932

Sheet M.P menú bbq 95€
C3: CALÇOTADA MAS BORONAT
C4: FICHA TÉCNICA PLATO
C7: ARTÍCULO | D7: Carpaccio de tomate con burrata i aceite albahaca
C8: TAPA | D8: ELABORADOS.
C9: unid. | D9: 12 | E9: Coste TOTAL | G9: =SUM(K12:K15) -> 1.9889 | H9: Coste KG: | J9: =G9/D9 -> 0.16574167
B11: ARTICULO | C11: KG | D11: €/UN | E11: BRUTO | F11: NETO | G11: %NETO | H11: %DESP | I11: DESP | J11: SUCIO | K11: € / RACION
B12: Tomate Cor de Bou. | C12: 0.2 | D12: =IF(ISNA(VLOOKUP(B12,'Listado de Artículos'!$B$16:$F$1328,5,0)),0,(VLOOKUP(B12,'Listado de Artículos'!$B$16:$F$1328,5,0))) -> 0 | E12: 1 | F12: 1 | G12: =IF(E12>0,(F12/E12),"") -> 1 | H12: =IF(E12>0,(100%-G12),"") -> 0 | I12: =IF(C12>0,(H12*C12/G12),"") -> 0 | J12: =IF(C12>0,(C12+I12),"") -> 0.2 | K12: =IF(D12>0,(D12*J12),"")
B13: Burrata 6 uni | C13: 0.5 | D13: =IF(ISNA(VLOOKUP(B13,'Listado de Artículos'!$B$16:$F$1328,5,0)),0,(VLOOKUP(B13,'Listado de Artículos'!$B$16:$F$1328,5,0))) -> 0.42 | E13: 1 | F13: 1 | G13: =IF(E13>0,(F13/E13),"") -> 1 | H13: =IF(E13>0,(100%-G13),"") -> 0 | I13: =IF(C13>0,(H13*C13/G13),"") -> 0 | J13: =IF(C13>0,(C13+I13),"") -> 0.5 | K13: =IF(D13>0,(D13*J13),"") -> 0.21
B14: Albahaca bandeja de 80 gr. 2,00€ | C14: 0.5 | D14: =IF(ISNA(VLOOKUP(B14,'Listado de Artículos'!$B$16:$F$1328,5,0)),0,(VLOOKUP(B14,'Listado de Artículos'!$B$16:$F$1328,5,0))) -> 3.5 | E14: 1 | F14: 1 | G14: =IF(E14>0,(F14/E14),"") -> 1 | H14: =IF(E14>0,(100%-G14),"") -> 0 | I14: =IF(C14>0,(H14*C14/G14),"") -> 0 | J14: =IF(C14>0,(C14+I14),"") -> 0.5 | K14: =IF(D14>0,(D14*J14),"") -> 1.75
B15: Sal negra en escamas. | C15: 0.005 | D15: =IF(ISNA(VLOOKUP(B15,'Listado de Artículos'!$B$16:$F$1328,5,0)),0,(VLOOKUP(B15,'Listado de Artículos'!$B$16:$F$1328,5,0))) -> 5.78 | E15: 1 | F15: 1 | G15: =IF(E15>0,(F15/E15),"") -> 1 | H15: =IF(E15>0,(100%-G15),"") -> 0 | I15: =IF(C15>0,(H15*C15/G15),"") -> 0 | J15: =IF(C15>0,(C15+I15),"") -> 0.005 | K15: =IF(D15>0,(D15*J15),"") -> 0.0289
C20: CALÇOTADA MAS BORONAT
C21: FICHA TÉCNICA PLATO
C24: ARTÍCULO | D24: Huevos rotos con jamón i foie
C25: TAPA | D25: ELABORADOS. | H25: COSTE UNID.
C26: PAX | D26: 1 | E26: Coste TOTAL | G26: =SUM(K29:K34) -> 2.0265 | H26: Coste unid: | J26: =G26/D26 -> 2.0265
B28: ARTICULO | C28: KG | D28: €/UN | E28: BRUTO | F28: NETO | G28: %NETO | H28: %DESP | I28: DESP | J28: SUCIO | K28: € / RACION
B29: Patata Monalisa. | C29: 0.2 | D29: =IF(ISNA(VLOOKUP(B29,'Listado de Artículos'!$B$16:$F$1328,5,0)),0,(VLOOKUP(B29,'Listado de Artículos'!$B$16:$F$1328,5,0))) -> 2 | E29: 1 | F29: 1 | G29: =IF(E29>0,(F29/E29),"") -> 1 | H29: =IF(E29>0,(100%-G29),"") -> 0 | I29: =IF(C29>0,(H29*C29/G29),"") -> 0 | J29: =IF(C29>0,(C29+I29),"") -> 0.2 | K29: =IF(D29>0,(D29*J29),"") -> 0.4
B30: Pimiento del padron. | C30: 0.1 | D30: =IF(ISNA(VLOOKUP(B30,'Listado de Artículos'!$B$16:$F$1328,5,0)),0,(VLOOKUP(B30,'Listado de Artículos'!$B$16:$F$1328,5,0))) -> 6.9 | E30: 1 | F30: 1 | G30: =IF(E30>0,(F30/E30),"") -> 1 | H30: =IF(E30>0,(100%-G30),"") -> 0 | I30: =IF(C30>0,(H30*C30/G30),"") -> 0 | J30: =IF(C30>0,(C30+I30),"") -> 0.1 | K30: =IF(D30>0,(D30*J30),"") -> 0.69
B31: Huevos "L" Granja Vidal, pqt de 6 unid: 1,60€ | C31: 2 | D31: =IF(ISNA(VLOOKUP(B31,'Listado de Artículos'!$B$16:$F$1328,5,0)),0,(VLOOKUP(B31,'Listado de Artículos'!$B$16:$F$1328,5,0))) -> 0.26 | E31: 1 | F31: 1 | G31: =IF(E31>0,(F31/E31),"") -> 1 | H31: =IF(E31>0,(100%-G31),"") -> 0 | I31: =IF(C31>0,(H31*C31/G31),"") -> 0 | J31: =IF(C31>0,(C31+I31),"") -> 2 | K31: =IF(D31>0,(D31*J31),"") -> 0.52
B32: Foie mi cuit 250g | C32: 0.02 | D32: =IF(ISNA(VLOOKUP(B32,'Listado de Artículos'!$B$16:$F$1328,5,0)),0,(VLOOKUP(B32,'Listado de Artículos'!$B$16:$F$1328,5,0))) -> 0.38 | E32: 1 | F32: 1 | G32: =IF(E32>0,(F32/E32),"") -> 1 | H32: =IF(E32>0,(100%-G32),"") -> 0 | I32: =IF(C32>0,(H32*C32/G32),"") -> 0 | J32: =IF(C32>0,(C32+I32),"") -> 0.02 | K32: =IF(D32>0,(D32*J32),"") -> 0.0076
B33: Sal negra en escamas. | C33: 0.005 | D33: =IF(ISNA(VLOOKUP(B33,'Listado de Artículos'!$B$16:$F$1328,5,0)),0,(VLOOKUP(B33,'Listado de Artículos'!$B$16:$F$1328,5,0))) -> 5.78 | E33: 1 | F33: 1 | G33: =IF(E33>0,(F33/E33),"") -> 1 | H33: =IF(E33>0,(100%-G33),"") -> 0 | I33: =IF(C33>0,(H33*C33/G33),"") -> 0 | J33: =IF(C33>0,(C33+I33),"") -> 0.005 | K33: =IF(D33>0,(D33*J33),"") -> 0.0289
B34: Paletilla jamón casa marcial | C34: 0.05 | D34: =IF(ISNA(VLOOKUP(B34,'Listado de Artículos'!$B$16:$F$1328,5,0)),0,(VLOOKUP(B34,'Listado de Artículos'!$B$16:$F$1328,5,0))) -> 7.6 | E34: 1 | F34: 1 | G34: =IF(E34>0,(F34/E34),"") -> 1 | H34: =IF(E34>0,(100%-G34),"") -> 0 | I34: =IF(C34>0,(H34*C34/G34),"") -> 0 | J34: =IF(C34>0,(C34+I34),"") -> 0.05 | K34: =IF(D34>0,(D34*J34),"") -> 0.38
C37: CALÇOTADA MAS BORONAT
C38: FICHA TÉCNICA PLATO
C41: ARTÍCULO | D41: Pulpo a la feira a la brasa
C42: TAPA | D42: ELABORADOS | H42: PRECIO DE VENTA P.V.P
C43: unid. | D43: 1 | E43: Coste TOTAL | G43: =SUM(K46:K52) -> 3.6789 | H43: Coste UNID: | J43: =G43/D43 -> 3.6789
B45: ARTICULO | C45: KG | D45: €/UN | E45: BRUTO | F45: NETO | G45: %NETO | H45: %DESP | I45: DESP | J45: SUCIO | K45: € / RACION
B46: Patata Monalisa. | C46: 0.1 | D46: =IF(ISNA(VLOOKUP(B46,'Listado de Artículos'!$B$16:$F$1328,5,0)),0,(VLOOKUP(B46,'Listado de Artículos'!$B$16:$F$1328,5,0))) -> 2 | E46: 1 | F46: 1 | G46: =IF(E46>0,(F46/E46),"") -> 1 | H46: =IF(E46>0,(100%-G46),"") -> 0 | I46: =IF(C46>0,(H46*C46/G46),"") -> 0 | J46: =IF(C46>0,(C46+I46),"") -> 0.1 | K46: =IF(D46>0,(D46*J46),"") -> 0.2
B47: Pata pulpo 250g | C47: 0.25 | D47: =IF(ISNA(VLOOKUP(B47,'Listado de Artículos'!$B$16:$F$1328,5,0)),0,(VLOOKUP(B47,'Listado de Artículos'!$B$16:$F$1328,5,0))) -> 10.5 | E47: 1 | F47: 1 | G47: =IF(E47>0,(F47/E47),"") -> 1 | H47: =IF(E47>0,(100%-G47),"") -> 0 | I47: =IF(C47>0,(H47*C47/G47),"") -> 0 | J47: =IF(C47>0,(C47+I47),"") -> 0.25 | K47: =IF(D47>0,(D47*J47),"") -> 2.625
B48: PIMENTON DULCE DE LA VERA | C48: 0.01 | D48: =IF(ISNA(VLOOKUP(B48,'Listado de Artículos'!$B$16:$F$1328,5,0)),0,(VLOOKUP(B48,'Listado de Artículos'!$B$16:$F$1328,5,0))) -> 23 | E48: 1 | F48: 1 | G48: =IF(E48>0,(F48/E48),"") -> 1 | H48: =IF(E48>0,(100%-G48),"") -> 0 | I48: =IF(C48>0,(H48*C48/G48),"") -> 0 | J48: =IF(C48>0,(C48+I48),"") -> 0.01 | K48: =IF(D48>0,(D48*J48),"") -> 0.23
B49: Sal negra en escamas. | C49: 0.005 | D49: =IF(ISNA(VLOOKUP(B49,'Listado de Artículos'!$B$16:$F$1328,5,0)),0,(VLOOKUP(B49,'Listado de Artículos'!$B$16:$F$1328,5,0))) -> 5.78 | E49: 1 | F49: 1 | G49: =IF(E49>0,(F49/E49),"") -> 1 | H49: =IF(E49>0,(100%-G49),"") -> 0 | I49: =IF(C49>0,(H49*C49/G49),"") -> 0 | J49: =IF(C49>0,(C49+I49),"") -> 0.005 | K49: =IF(D49>0,(D49*J49),"") -> 0.0289
B50: ACEITE DE OLIVA SUAVE 5 LT | C50: 0.1 | D50: =IF(ISNA(VLOOKUP(B50,'Listado de Artículos'!$B$16:$F$1328,5,0)),0,(VLOOKUP(B50,'Listado de Artículos'!$B$16:$F$1328,5,0))) -> 5.95 | E50: 1 | F50: 1 | G50: =IF(E50>0,(F50/E50),"") -> 1 | H50: =IF(E50>0,(100%-G50),"") -> 0 | I50: =IF(C50>0,(H50*C50/G50),"") -> 0 | J50: =IF(C50>0,(C50+I50),"") -> 0.1 | K50: =IF(D50>0,(D50*J50),"") -> 0.595
C55: CALÇOTADA MAS BORONAT
C56: FICHA TÉCNICA PLATO
C59: ARTÍCULO | D59: Chuleta lomo bajo con pimiento de piquillo y alcachofa
C60: TAPA | D60: ELABORADOS.
C61: unid. | D61: 1 | E61: Coste TOTAL | G61: =SUM(K64:K66) -> 15.2695 | H61: Coste UNID: | J61: =G61/D61 -> 15.2695
B63: ARTICULO | C63: KG | D63: €/UN | E63: BRUTO | F63: NETO | G63: %NETO | H63: %DESP | I63: DESP | J63: SUCIO | K63: € / RACION
B64: Chuleta lomo bajo 300-350g | C64: 1 | D64: 9.95 | E64: 1 | F64: 1 | G64: =IF(E64>0,(F64/E64),"") -> 1 | H64: =IF(E64>0,(100%-G64),"") -> 0 | I64: =IF(C64>0,(H64*C64/G64),"") -> 0 | J64: =IF(C64>0,(C64+I64),"") -> 1 | K64: =IF(D64>0,(D64*J64),"") -> 9.95
...

Sheet Menú bbq 95€
A2: MENU BBQ 95€ 13-03-26
A4: Entrantes | B4: P.V.P | C4: NETO | D4: COSTO | E4: FOOD COST
A5: CALÇOTADA. APERITIVO CARTA | B5: GR O KG. | C5: PRECIO KG | D5: EUROS/RACION.
A6: Carpaccio de tomate con burrata y aceite albahaca | B6: 1 | C6: =IF(ISNA(VLOOKUP(A6,'Listado de Artículos'!$B$16:$F$1328,5,0)),0,(VLOOKUP(A6,'Listado de Artículos'!$B$16:$F$1328,5,0))) -> 0.16574167 | D6: =B6*C6 -> 0.16574167
A7: Huevos rotos con jamón y foie | B7: 1 | C7: =IF(ISNA(VLOOKUP(A7,'Listado de Artículos'!$B$16:$F$1328,5,0)),0,(VLOOKUP(A7,'Listado de Artículos'!$B$16:$F$1328,5,0))) -> 2.0265 | D7: =B7*C7 -> 2.0265
A8: Vaso Pulpo a la feira | B8: 1 | C8: =IF(ISNA(VLOOKUP(A8,'Listado de Artículos'!$B$16:$F$1328,5,0)),0,(VLOOKUP(A8,'Listado de Artículos'!$B$16:$F$1328,5,0))) -> 3.6789 | D8: =B8*C8 -> 3.6789
A9: Plato principal
A10: Chuleta lomo bajo con pimiento del piquillo y alcachofa | B10: 1 | C10: =IF(ISNA(VLOOKUP(A10,'Listado de Artículos'!$B$16:$F$1328,5,0)),0,(VLOOKUP(A10,'Listado de Artículos'!$B$16:$F$1328,5,0))) -> 15.2695 | D10: =B10*C10 -> 15.2695
A11: Cafe Natural. 1 kg. 120 cafes. 24,48€ .kg. 0,22 unid | B11: 1 | C11: =IF(ISNA(VLOOKUP(A11,'Listado de Artículos'!$B$16:$F$1328,5,0)),0,(VLOOKUP(A11,'Listado de Artículos'!$B$16:$F$1328,5,0))) -> 0.65 | D11: =B11*C11 -> 0.65
A12: Agua Fon vella 1 LT Caja de 12 unid. | B12: 0.3 | C12: =IF(ISNA(VLOOKUP(A12,'Listado de Artículos'!$B$16:$F$1328,5,0)),0,(VLOOKUP(A12,'Listado de Artículos'!$B$16:$F$1328,5,0))) -> 0.8 | D12: =B12*C12 -> 0.24
D13: 9
A14: ESCANDALLO | B14: 95 | C14: =B14/1.1 -> 86.363636 | D14: =SUM(D6:D13) -> 31.030642 | E14: =(D14*100/C14)/100 -> 0.35930217
C16: =C14-D14 -> 55.332995
B17: =16.5*10% -> 1.65
B18: =16.5-1.65 -> 14.85

Sheet M.P CALÇOTADA
C3: CALÇOTADA MAS BORONAT
C4: FICHA TÉCNICA PLATO
C7: ARTÍCULO | D7: Vermouth rojo
C8: TAPA | D8: ELABORADOS.
C9: unid. | D9: 1 | E9: Coste TOTAL | G9: =SUM(K12:K14) -> 1.45075 | H9: Coste KG: | J9: =G9/D9 -> 1.45075
B11: ARTICULO | C11: KG | D11: €/UN | E11: BRUTO | F11: NETO | G11: %NETO | H11: %DESP | I11: DESP | J11: SUCIO | K11: € / RACION
B12: Mirrah. rojo 15% 5 l. 15,01€ precio backin box | C12: 0.1 | D12: =IF(ISNA(VLOOKUP(B12,'Listado de Artículos'!$B$16:$F$1328,5,0)),0,(VLOOKUP(B12,'Listado de Artículos'!$B$16:$F$1328,5,0))) -> 5.62 | E12: 1 | F12: 1 | G12: =IF(E12>0,(F12/E12),"") -> 1 | H12: =IF(E12>0,(100%-G12),"") -> 0 | I12: =IF(C12>0,(H12*C12/G12),"") -> 0 | J12: =IF(C12>0,(C12+I12),"") -> 0.1 | K12: =IF(D12>0,(D12*J12),"") -> 0.562
B13: Naranja extra de mesa. | C13: 0.025 | D13: =IF(ISNA(VLOOKUP(B13,'Listado de Artículos'!$B$16:$F$1328,5,0)),0,(VLOOKUP(B13,'Listado de Artículos'!$B$16:$F$1328,5,0))) -> 17.55 | E13: 1 | F13: 1 | G13: =IF(E13>0,(F13/E13),"") -> 1 | H13: =IF(E13>0,(100%-G13),"") -> 0 | I13: =IF(C13>0,(H13*C13/G13),"") -> 0 | J13: =IF(C13>0,(C13+I13),"") -> 0.025 | K13: =IF(D13>0,(D13*J13),"") -> 0.43875
B14: OLIVAS RELLENAS GIGANTES LATA 2 KG. 4,79€ | C14: 0.05 | D14: =IF(ISNA(VLOOKUP(B14,'Listado de Artículos'!$B$16:$F$1328,5,0)),0,(VLOOKUP(B14,'Listado de Artículos'!$B$16:$F$1328,5,0))) -> 9 | E14: 1 | F14: 1 | G14: =IF(E14>0,(F14/E14),"") -> 1 | H14: =IF(E14>0,(100%-G14),"") -> 0 | I14: =IF(C14>0,(H14*C14/G14),"") -> 0 | J14: =IF(C14>0,(C14+I14),"") -> 0.05 | K14: =IF(D14>0,(D14*J14),"") -> 0.45
C19: CALÇOTADA MAS BORONAT
C20: FICHA TÉCNICA PLATO
C23: ARTÍCULO | D23: Naranja con miel
C24: TAPA | D24: ELABORADOS. | H24: COSTE UNID.
C25: PAX | D25: 1 | E25: Coste TOTAL | G25: =SUM(K28:K29) -> 2.6723 | H25: Coste unid: | J25: =G25/D25 -> 2.6723
B27: ARTICULO | C27: KG | D27: €/UN | E27: BRUTO | F27: NETO | G27: %NETO | H27: %DESP | I27: DESP | J27: SUCIO | K27: € / RACION
B28: Naranja extra de mesa. | C28: 0.15 | D28: =IF(ISNA(VLOOKUP(B28,'Listado de Artículos'!$B$16:$F$1328,5,0)),0,(VLOOKUP(B28,'Listado de Artículos'!$B$16:$F$1328,5,0))) -> 17.55 | E28: 1 | F28: 1 | G28: =IF(E28>0,(F28/E28),"") -> 1 | H28: =IF(E28>0,(100%-G28),"") -> 0 | I28: =IF(C28>0,(H28*C28/G28),"") -> 0 | J28: =IF(C28>0,(C28+I28),"") -> 0.15 | K28: =IF(D28>0,(D28*J28),"") -> 2.6325
B29: Miel del perello | C29: 0.01 | D29: =IF(ISNA(VLOOKUP(B29,'Listado de Artículos'!$B$16:$F$1328,5,0)),0,(VLOOKUP(B29,'Listado de Artículos'!$B$16:$F$1328,5,0))) -> 3.98 | E29: 1 | F29: 1 | G29: =IF(E29>0,(F29/E29),"") -> 1 | H29: =IF(E29>0,(100%-G29),"") -> 0 | I29: =IF(C29>0,(H29*C29/G29),"") -> 0 | J29: =IF(C29>0,(C29+I29),"") -> 0.01 | K29: =IF(D29>0,(D29*J29),"") -> 0.0398
C32: CALÇOTADA MAS BORONAT
C33: FICHA TÉCNICA PLATO
C36: ARTÍCULO | D36: Crema catalana.
C37: TAPA | D37: ELABORADOS | H37: PRECIO DE VENTA P.V.P
C38: unid. | D38: 7 | E38: Coste TOTAL | G38: =SUM(K41:K47) -> 5.88848 | H38: Coste UNID: | J38: =G38/D38 -> 0.84121143
B40: ARTICULO | C40: KG | D40: €/UN | E40: BRUTO | F40: NETO | G40: %NETO | H40: %DESP | I40: DESP | J40: SUCIO | K40: € / RACION
B41: Leche entera. | C41: 1 | D41: =IF(ISNA(VLOOKUP(B41,'Listado de Artículos'!$B$16:$F$1328,5,0)),0,(VLOOKUP(B41,'Listado de Artículos'!$B$16:$F$1328,5,0))) -> 2.8 | E41: 1 | F41: 1 | G41: =IF(E41>0,(F41/E41),"") -> 1 | H41: =IF(E41>0,(100%-G41),"") -> 0 | I41: =IF(C41>0,(H41*C41/G41),"") -> 0 | J41: =IF(C41>0,(C41+I41),"") -> 1 | K41: =IF(D41>0,(D41*J41),"") -> 2.8
B42: CANELA EN RAMA BOTE | C42: 0.016 | D42: =IF(ISNA(VLOOKUP(B42,'Listado de Artículos'!$B$16:$F$1328,5,0)),0,(VLOOKUP(B42,'Listado de Artículos'!$B$16:$F$1328,5,0))) -> 5.73 | E42: 1 | F42: 1 | G42: =IF(E42>0,(F42/E42),"") -> 1 | H42: =IF(E42>0,(100%-G42),"") -> 0 | I42: =IF(C42>0,(H42*C42/G42),"") -> 0 | J42: =IF(C42>0,(C42+I42),"") -> 0.016 | K42: =IF(D42>0,(D42*J42),"") -> 0.09168
B43: Naranja de zumo. | C43: 0.04 | D43: =IF(ISNA(VLOOKUP(B43,'Listado de Artículos'!$B$16:$F$1328,5,0)),0,(VLOOKUP(B43,'Listado de Artículos'!$B$16:$F$1328,5,0))) -> 21.5 | E43: 1 | F43: 1 | G43: =IF(E43>0,(F43/E43),"") -> 1 | H43: =IF(E43>0,(100%-G43),"") -> 0 | I43: =IF(C43>0,(H43*C43/G43),"") -> 0 | J43: =IF(C43>0,(C43+I43),"") -> 0.04 | K43: =IF(D43>0,(D43*J43),"") -> 0.86
B44: Limones extra. | C44: 0.04 | D44: =IF(ISNA(VLOOKUP(B44,'Listado de Artículos'!$B$16:$F$1328,5,0)),0,(VLOOKUP(B44,'Listado de Artículos'!$B$16:$F$1328,5,0))) -> 1.38 | E44: 1 | F44: 1 | G44: =IF(E44>0,(F44/E44),"") -> 1 | H44: =IF(E44>0,(100%-G44),"") -> 0 | I44: =IF(C44>0,(H44*C44/G44),"") -> 0 | J44: =IF(C44>0,(C44+I44),"") -> 0.04 | K44: =IF(D44>0,(D44*J44),"") -> 0.0552
B45: AZUCAR | C45: 0.14 | D45: =IF(ISNA(VLOOKUP(B45,'Listado de Artículos'!$B$16:$F$1328,5,0)),0,(VLOOKUP(B45,'Listado de Artículos'!$B$16:$F$1328,5,0))) -> 0.82 | E45: 1 | F45: 1 | G45: =IF(E45>0,(F45/E45),"") -> 1 | H45: =IF(E45>0,(100%-G45),"") -> 0 | I45: =IF(C45>0,(H45*C45/G45),"") -> 0 | J45: =IF(C45>0,(C45+I45),"") -> 0.14 | K45: =IF(D45>0,(D45*J45),"") -> 0.1148
B46: MAIZENA 700 GR. | C46: 0.04 | D46: =IF(ISNA(VLOOKUP(B46,'Listado de Artículos'!$B$16:$F$1328,5,0)),0,(VLOOKUP(B46,'Listado de Artículos'!$B$16:$F$1328,5,0))) -> 3.67 | E46: 1 | F46: 1 | G46: =IF(E46>0,(F46/E46),"") -> 1 | H46: =IF(E46>0,(100%-G46),"") -> 0 | I46: =IF(C46>0,(H46*C46/G46),"") -> 0 | J46: =IF(C46>0,(C46+I46),"") -> 0.04 | K46: =IF(D46>0,(D46*J46),"") -> 0.1468
B47: Huevos "L" Granja Vidal, pqt de 6 unid: 1,60€ | C47: 7 | D47: =IF(ISNA(VLOOKUP(B47,'Listado de Artículos'!$B$16:$F$1328,5,0)),0,(VLOOKUP(B47,'Listado de Artículos'!$B$16:$F$1328,5,0))) -> 0.26 | E47: 1 | F47: 1 | G47: =IF(E47>0,(F47/E47),"") -> 1 | H47: =IF(E47>0,(100%-G47),"") -> 0 | I47: =IF(C47>0,(H47*C47/G47),"") -> 0 | J47: =IF(C47>0,(C47+I47),"") -> 7 | K47: =IF(D47>0,(D47*J47),"") -> 1.82
C50: CALÇOTADA MAS BORONAT
C51: FICHA TÉCNICA PLATO
C54: ARTÍCULO | D54: Crema Catalana quemada con carquiñoli.
C55: TAPA | D55: ELABORADOS.
C56: unid. | D56: 1 | E56: Coste TOTAL | G56: =SUM(K59:K61) -> 0.7621 | H56: Coste UNID: | J56: =G56/D56 -> 0.7621
B58: ARTICULO | C58: KG | D58: €/UN | E58: BRUTO | F58: NETO | G58: %NETO | H58: %DESP | I58: DESP | J58: SUCIO | K58: € / RACION
B59: Crema Catalana. | C59: 1 | D59: =IF(ISNA(VLOOKUP(B59,'Listado de Artículos'!$B$16:$F$1328,5,0)),0,(VLOOKUP(B59,'Listado de Artículos'!$B$16:$F$1328,5,0))) -> 0.5 | E59: 1 | F59: 1 | G59: =IF(E59>0,(F59/E59),"") -> 1 | H59: =IF(E59>0,(100%-G59),"") -> 0 | I59: =IF(C59>0,(H59*C59/G59),"") -> 0 | J59: =IF(C59>0,(C59+I59),"") -> 1 | K59: =IF(D59>0,(D59*J59),"") -> 0.5
B60: AZUCAR | C60: 0.025 | D60: =IF(ISNA(VLOOKUP(B60,'Listado de Artículos'!$B$16:$F$1328,5,0)),0,(VLOOKUP(B60,'Listado de Artículos'!$B$16:$F$1328,5,0))) -> 0.82 | E60: 1 | F60: 1 | G60: =IF(E60>0,(F60/E60),"") -> 1 | H60: =IF(E60>0,(100%-G60),"") -> 0 | I60: =IF(C60>0,(H60*C60/G60),"") -> 0 | J60: =IF(C60>0,(C60+I60),"") -> 0.025 | K60: =IF(D60>0,(D60*J60),"") -> 0.0205
B61: Carquiñolis. 200 gr. 3,75€ pqt | C61: 0.01 | D61: =IF(ISNA(VLOOKUP(B61,'Listado de Artículos'!$B$16:$F$1328,5,0)),0,(VLOOKUP(B61,'Listado de Artículos'!$B$16:$F$1328,5,0))) -> 24.16 | E61: 1 | F61: 1 | G61: =IF(E61>0,(F61/E61),"") -> 1 | H61: =IF(E61>0,(100%-G61),"") -> 0 | I61: =IF(C61>0,(H61*C61/G61),"") -> 0 | J61: =IF(C61>0,(C61+I61),"") -> 0.01 | K61: =IF(D61>0,(D61*J61),"") -> 0.2416
C64: CALÇOTADA MAS BORONAT
...

Sheet MENU CALÇOTADA
A2: MENU CALÇOTADA CARTA. 15-12-25
A4: APERITIVO. | B4: P.V.P | C4: NETO | D4: COSTO | E4: FOOD COST
A5: CALÇOTADA. APERITIVO CARTA | B5: GR O KG. | C5: PRECIO KG | D5: EUROS/RACION.
A6: Aperitivo completo para calçotada. | B6: 1 | C6: =IF(ISNA(VLOOKUP(A6,'Listado de Artículos'!$B$16:$F$1328,5,0)),0,(VLOOKUP(A6,'Listado de Artículos'!$B$16:$F$1328,5,0))) -> 0.44 | D6: =B6*C6 -> 0.44
A7: MENU Calçotada Vermuth | B7: 1 | C7: =IF(ISNA(VLOOKUP(A7,'Listado de Artículos'!$B$16:$F$1328,5,0)),0,(VLOOKUP(A7,'Listado de Artículos'!$B$16:$F$1328,5,0))) -> 0.47 | D7: =B7*C7 -> 0.47
A8: Agua Fon vella 1 LT Caja de 12 unid. | B8: 0.25 | C8: =IF(ISNA(VLOOKUP(A8,'Listado de Artículos'!$B$16:$F$1328,5,0)),0,(VLOOKUP(A8,'Listado de Artículos'!$B$16:$F$1328,5,0))) -> 0.8 | D8: =B8*C8 -> 0.2
A9: Vino negro Calçotada. BAG IN BOX. 20 LT. NEGRO. CELLER MAS ROIG. (35,57€). | B9: 0.35 | C9: 2.38 | D9: =B9*C9 -> 0.833
A10: CALÇOTADA ILIMITADA.
A11: Calçots Valls. Majols. crudos | B11: 15 | C11: =IF(ISNA(VLOOKUP(A11,'Listado de Artículos'!$B$16:$F$1328,5,0)),0,(VLOOKUP(A11,'Listado de Artículos'!$B$16:$F$1328,5,0))) -> 0.16 | D11: =B11*C11 -> 2.4
A12: Salsa romesco. | B12: 0.125 | C12: =IF(ISNA(VLOOKUP(A12,'Listado de Artículos'!$B$16:$F$1328,5,0)),0,(VLOOKUP(A12,'Listado de Artículos'!$B$16:$F$1328,5,0))) -> 2.94 | D12: =B12*C12 -> 0.3675
A13: EN MESA.
A14: Ensalada para calçotada terminada lechuga de pages. | B14: 1 | C14: =IF(ISNA(VLOOKUP(A14,'Listado de Artículos'!$B$16:$F$1328,5,0)),0,(VLOOKUP(A14,'Listado de Artículos'!$B$16:$F$1328,5,0))) -> 0.7 | D14: =B14*C14 -> 0.7
A15: MENU CALÇOTADA. CESTA DE PAN, TOMATE Y AJO. | B15: 1 | C15: =IF(ISNA(VLOOKUP(A15,'Listado de Artículos'!$B$16:$F$1328,5,0)),0,(VLOOKUP(A15,'Listado de Artículos'!$B$16:$F$1328,5,0))) -> 0.54 | D15: =B15*C15 -> 0.54
A16: MENU CALÇOTADA BOTIFARRA MONGETES BLANCAS | B16: 1 | C16: =IF(ISNA(VLOOKUP(A16,'Listado de Artículos'!$B$16:$F$1328,5,0)),0,(VLOOKUP(A16,'Listado de Artículos'!$B$16:$F$1328,5,0))) -> 0.84 | D16: =B16*C16 -> 0.84
A17: Salsa Allioli. natural. bote de 1 lt. | B17: 0.03 | C17: =IF(ISNA(VLOOKUP(A17,'Listado de Artículos'!$B$16:$F$1328,5,0)),0,(VLOOKUP(A17,'Listado de Artículos'!$B$16:$F$1328,5,0))) -> 3.85 | D17: =B17*C17 -> 0.1155
A18: PRINCIPAL
A19: MENU CALÇOTADA CORDERO Y BOTIFARRA NEGRA. | B19: 1 | C19: =IF(ISNA(VLOOKUP(A19,'Listado de Artículos'!$B$16:$F$1328,5,0)),0,(VLOOKUP(A19,'Listado de Artículos'!$B$16:$F$1328,5,0))) -> 2.8824 | D19: =B19*C19 -> 2.8824
A20: MENU CALÇOTADA GUARNICION DE CORDERO. | B20: 1 | C20: =IF(ISNA(VLOOKUP(A20,'Listado de Artículos'!$B$16:$F$1328,5,0)),0,(VLOOKUP(A20,'Listado de Artículos'!$B$16:$F$1328,5,0))) -> 0.96 | D20: =B20*C20 -> 0.96
A21: POSTRES
A22: Crema Catalana. | B22: 1 | C22: =IF(ISNA(VLOOKUP(A22,'Listado de Artículos'!$B$16:$F$1328,5,0)),0,(VLOOKUP(A22,'Listado de Artículos'!$B$16:$F$1328,5,0))) -> 0.5 | D22: =B22*C22 -> 0.5
A23: MENU CALÇOTADA NARANJA CON MIEL. POR PAX. | B23: 1 | C23: =IF(ISNA(VLOOKUP(A23,'Listado de Artículos'!$B$16:$F$1328,5,0)),0,(VLOOKUP(A23,'Listado de Artículos'!$B$16:$F$1328,5,0))) -> 0.37 | D23: =B23*C23 -> 0.37
A24: POSTRES
A25: CLOS PINELL TERRA TINTO ALTA | B25: 0.25 | C25: =IF(ISNA(VLOOKUP(A25,'Listado de Artículos'!$B$16:$F$1328,5,0)),0,(VLOOKUP(A25,'Listado de Artículos'!$B$16:$F$1328,5,0))) -> 0.9 | D25: =B25*C25 -> 0.225
A26: CAVA ROGER DE FLOR | B26: 0.15 | C26: =IF(ISNA(VLOOKUP(A26,'Listado de Artículos'!$B$16:$F$1328,5,0)),0,(VLOOKUP(A26,'Listado de Artículos'!$B$16:$F$1328,5,0))) -> 0 | D26: =B26*C26 -> 0
A27: Cafe Natural. 1 kg. 120 cafes. 24,48€ .kg. 0,22 unid | B27: 1 | C27: =IF(ISNA(VLOOKUP(A27,'Listado de Artículos'!$B$16:$F$1328,5,0)),0,(VLOOKUP(A27,'Listado de Artículos'!$B$16:$F$1328,5,0))) -> 0.65 | D27: =B27*C27 -> 0.65
B28: 0.3 | C28: =IF(ISNA(VLOOKUP(A28,'Listado de Artículos'!$B$16:$F$1328,5,0)),0,(VLOOKUP(A28,'Listado de Artículos'!$B$16:$F$1328,5,0))) -> 0 | D28: =B28*C28 -> 0
A30: ESCANDALLO | B30: 49.9 | C30: =B30/1.1 -> 45.363636 | D30: =SUM(D6:D29) -> 12.4934 | E30: =(D30*100/C30)/100 -> 0.27540561

Sheet Hoja 1

Sheet M.P Aperitivos
B3: Boda 31-1
B4: FICHA TÉCNICA PLATO
B7: ARTÍCULO | C7: Patatas Bravas
B8: TAPA | C8: ELABORADOS | G8: PRECIO DE VENTA P.V.P
B9: unid. | C9: 1 | D9: Coste TOTAL | F9: =SUM(J12:J18) -> 1.5774 | G9: Coste UNID: | I9: =F9/C9 -> 1.5774
A11: ARTICULO | B11: KG | C11: €/UN | D11: BRUTO | E11: NETO | F11: %NETO | G11: %DESP | H11: DESP | I11: SUCIO | J11: € / RACION
A12: Patata Monalisa. | B12: 0.35 | C12: =IF(ISNA(VLOOKUP(A12,'Listado de Artículos'!$B$16:$F$1328,5,0)),0,(VLOOKUP(A12,'Listado de Artículos'!$B$16:$F$1328,5,0))) -> 2 | D12: 1 | E12: 1 | F12: =IF(D12>0,(E12/D12),"") -> 1 | G12: 0.005 | H12: =IF(B12>0,(G12*B12/F12),"") -> 0.00175 | I12: =IF(B12>0,(B12+H12),"") -> 0.35175 | J12: =IF(C12>0,(C12*I12),"") -> 0.7035
A13: Salsa Brava. bote de 1,850. precio bote 5,20€. Coosur. | B13: 0.1 | C13: =IF(ISNA(VLOOKUP(A13,'Listado de Artículos'!$B$16:$F$1328,5,0)),0,(VLOOKUP(A13,'Listado de Artículos'!$B$16:$F$1328,5,0))) -> 1.55 | D13: 1 | E13: 1 | F13: =IF(D13>0,(E13/D13),"") -> 1 | G13: =IF(D13>0,(100%-F13),"") -> 0 | H13: =IF(B13>0,(G13*B13/F13),"") -> 0 | I13: =IF(B13>0,(B13+H13),"") -> 0.1 | J13: =IF(C13>0,(C13*I13),"") -> 0.155
A14: Sal negra en escamas. | B14: 0.005 | C14: =IF(ISNA(VLOOKUP(A14,'Listado de Artículos'!$B$16:$F$1328,5,0)),0,(VLOOKUP(A14,'Listado de Artículos'!$B$16:$F$1328,5,0))) -> 5.78 | D14: 1 | E14: 1 | F14: =IF(D14>0,(E14/D14),"") -> 1 | G14: =IF(D14>0,(100%-F14),"") -> 0 | H14: =IF(B14>0,(G14*B14/F14),"") -> 0 | I14: =IF(B14>0,(B14+H14),"") -> 0.005 | J14: =IF(C14>0,(C14*I14),"") -> 0.0289
A15: Pimiento del padron. | B15: 0.1 | C15: =IF(ISNA(VLOOKUP(A15,'Listado de Artículos'!$B$16:$F$1328,5,0)),0,(VLOOKUP(A15,'Listado de Artículos'!$B$16:$F$1328,5,0))) -> 6.9 | D15: 1 | E15: 1 | F15: =IF(D15>0,(E15/D15),"") -> 1 | G15: =IF(D15>0,(100%-F15),"") -> 0 | H15: =IF(B15>0,(G15*B15/F15),"") -> 0 | I15: =IF(B15>0,(B15+H15),"") -> 0.1 | J15: =IF(C15>0,(C15*I15),"") -> 0.69
B22: ARTÍCULO | C22: Tabla de queso con pan de cristal
B23: TAPA | C23: ELABORADOS | G23: PRECIO DE VENTA P.V.P
B24: unid. | C24: 1 | D24: Coste TOTAL | F24: =SUM(J27:J37) -> 8.791 | G24: Coste UNID: | I24: =F24/C24 -> 8.791
A26: ARTICULO | B26: KG | C26: €/UN | D26: BRUTO | E26: NETO | F26: %NETO | G26: %DESP | H26: DESP | I26: SUCIO | J26: € / RACION
A27: Queso Altejo moli de ger Vaca. | B27: 0.07 | C27: =IF(ISNA(VLOOKUP(A27,'Listado de Artículos'!$B$16:$F$1328,5,0)),0,(VLOOKUP(A27,'Listado de Artículos'!$B$16:$F$1328,5,0))) -> 0.03 | D27: 1 | E27: 1 | F27: =IF(D27>0,(E27/D27),"") -> 1 | G27: =IF(D27>0,(100%-F27),"") -> 0 | H27: =IF(B27>0,(G27*B27/F27),"") -> 0 | I27: =IF(B27>0,(B27+H27),"") -> 0.07 | J27: =IF(C27>0,(C27*I27),"") -> 0.0021
A28: Queso Garrotxa Cabra. Bauma. | B28: 0.04 | C28: =IF(ISNA(VLOOKUP(A28,'Listado de Artículos'!$B$16:$F$1328,5,0)),0,(VLOOKUP(A28,'Listado de Artículos'!$B$16:$F$1328,5,0))) -> 0.01 | D28: 1 | E28: 1 | F28: =IF(D28>0,(E28/D28),"") -> 1 | G28: =IF(D28>0,(100%-F28),"") -> 0 | H28: =IF(B28>0,(G28*B28/F28),"") -> 0 | I28: =IF(B28>0,(B28+H28),"") -> 0.04 | J28: =IF(C28>0,(C28*I28),"") -> 0.0004
A29: Queso Azul Blau Cereta. Moli de ger. | B29: 0.03 | C29: =IF(ISNA(VLOOKUP(A29,'Listado de Artículos'!$B$16:$F$1328,5,0)),0,(VLOOKUP(A29,'Listado de Artículos'!$B$16:$F$1328,5,0))) -> 2.95 | D29: 1 | E29: 1 | F29: =IF(D29>0,(E29/D29),"") -> 1 | G29: =IF(D29>0,(100%-F29),"") -> 0 | H29: =IF(B29>0,(G29*B29/F29),"") -> 0 | I29: =IF(B29>0,(B29+H29),"") -> 0.03 | J29: =IF(C29>0,(C29*I29),"") -> 0.0885
A30: Pan cristal precortado. (3,200 gr). 64 *50. 26,78€ Caja. 0,20€ medio trozo. | B30: 3 | C30: =IF(ISNA(VLOOKUP(A30,'Listado de Artículos'!$B$16:$F$1328,5,0)),0,(VLOOKUP(A30,'Listado de Artículos'!$B$16:$F$1328,5,0))) -> 2.9 | D30: 1 | E30: 1 | F30: =IF(D30>0,(E30/D30),"") -> 1 | G30: =IF(D30>0,(100%-F30),"") -> 0 | H30: =IF(B30>0,(G30*B30/F30),"") -> 0 | I30: =IF(B30>0,(B30+H30),"") -> 3 | J30: =IF(C30>0,(C30*I30),"") -> 8.7
B31: 0.3 | C31: =IF(ISNA(VLOOKUP(A31,'Listado de Artículos'!$B$16:$F$1328,5,0)),0,(VLOOKUP(A31,'Listado de Artículos'!$B$16:$F$1328,5,0))) -> 0 | D31: 1 | E31: 1 | F31: =IF(D31>0,(E31/D31),"") -> 1 | G31: =IF(D31>0,(100%-F31),"") -> 0 | H31: =IF(B31>0,(G31*B31/F31),"") -> 0 | I31: =IF(B31>0,(B31+H31),"") -> 0.3 | J31: =IF(C31>0,(C31*I31),"")
B32: 0.25 | C32: =IF(ISNA(VLOOKUP(A32,'Listado de Artículos'!$B$16:$F$1328,5,0)),0,(VLOOKUP(A32,'Listado de Artículos'!$B$16:$F$1328,5,0))) -> 0 | D32: 1 | E32: 1 | F32: =IF(D32>0,(E32/D32),"") -> 1 | G32: =IF(D32>0,(100%-F32),"") -> 0 | H32: =IF(B32>0,(G32*B32/F32),"") -> 0 | I32: =IF(B32>0,(B32+H32),"") -> 0.25 | J32: =IF(C32>0,(C32*I32),"")
B33: 1 | C33: =IF(ISNA(VLOOKUP(A33,'Listado de Artículos'!$B$16:$F$1328,5,0)),0,(VLOOKUP(A33,'Listado de Artículos'!$B$16:$F$1328,5,0))) -> 0 | D33: 1 | E33: 1 | F33: =IF(D33>0,(E33/D33),"") -> 1 | G33: =IF(D33>0,(100%-F33),"") -> 0 | H33: =IF(B33>0,(G33*B33/F33),"") -> 0 | I33: =IF(B33>0,(B33+H33),"") -> 1 | J33: =IF(C33>0,(C33*I33),"")
B34: 1 | C34: =IF(ISNA(VLOOKUP(A34,'Listado de Artículos'!$B$16:$F$1328,5,0)),0,(VLOOKUP(A34,'Listado de Artículos'!$B$16:$F$1328,5,0))) -> 0 | D34: 1 | E34: 1 | F34: =IF(D34>0,(E34/D34),"") -> 1 | G34: =IF(D34>0,(100%-F34),"") -> 0 | H34: =IF(B34>0,(G34*B34/F34),"") -> 0 | I34: =IF(B34>0,(B34+H34),"") -> 1 | J34: =IF(C34>0,(C34*I34),"")
B35: 1 | C35: =IF(ISNA(VLOOKUP(A35,'Listado de Artículos'!$B$16:$F$1328,5,0)),0,(VLOOKUP(A35,'Listado de Artículos'!$B$16:$F$1328,5,0))) -> 0 | D35: 1 | E35: 1 | F35: =IF(D35>0,(E35/D35),"") -> 1 | G35: =IF(D35>0,(100%-F35),"") -> 0 | H35: =IF(B35>0,(G35*B35/F35),"") -> 0 | I35: =IF(B35>0,(B35+H35),"") -> 1 | J35: =IF(C35>0,(C35*I35),"")
B36: 1 | C36: =IF(ISNA(VLOOKUP(A36,'Listado de Artículos'!$B$16:$F$1328,5,0)),0,(VLOOKUP(A36,'Listado de Artículos'!$B$16:$F$1328,5,0))) -> 0 | D36: 1 | E36: 1 | F36: =IF(D36>0,(E36/D36),"") -> 1 | G36: =IF(D36>0,(100%-F36),"") -> 0 | H36: =IF(B36>0,(G36*B36/F36),"") -> 0 | I36: =IF(B36>0,(B36+H36),"") -> 1 | J36: =IF(C36>0,(C36*I36),"")
B37: 2 | C37: =IF(ISNA(VLOOKUP(A37,'Listado de Artículos'!$B$16:$F$1328,5,0)),0,(VLOOKUP(A37,'Listado de Artículos'!$B$16:$F$1328,5,0))) -> 0 | D37: 1 | E37: 1 | F37: =IF(D37>0,(E37/D37),"") -> 1 | G37: =IF(D37>0,(100%-F37),"") -> 0 | H37: =IF(B37>0,(G37*B37/F37),"") -> 0 | I37: =IF(B37>0,(B37+H37),"") -> 2 | J37: =IF(C37>0,(C37*I37),"")
A39: =1500/60 -> 25
B41: ARTÍCULO | C41: Tabla de jamón iberico con pan de cristal
B42: TAPA | C42: ELABORADOS | G42: PRECIO DE VENTA P.V.P
B43: unid. | C43: 1 | D43: Coste TOTAL | F43: =SUM(J46:J48) -> 10.025 | G43: Coste UNID: | I43: =F43/C43 -> 10.025
A45: ARTICULO | B45: KG | C45: €/UN | D45: BRUTO | E45: NETO | F45: %NETO | G45: %DESP | H45: DESP | I45: SUCIO | J45: € / RACION
A46: Paletilla jamón casa marcial | B46: 0.15 | C46: =IF(ISNA(VLOOKUP(A46,'Listado de Artículos'!$B$16:$F$1328,5,0)),0,(VLOOKUP(A46,'Listado de Artículos'!$B$16:$F$1328,5,0))) -> 7.6 | D46: 1 | E46: 1 | F46: =IF(D46>0,(E46/D46),"") -> 1 | G46: =IF(D46>0,(100%-F46),"") -> 0 | H46: =IF(B46>0,(G46*B46/F46),"") -> 0 | I46: =IF(B46>0,(B46+H46),"") -> 0.15 | J46: =IF(C46>0,(C46*I46),"") -> 1.14
A47: Pan cristal precortado. (3,200 gr). 64 *50. 26,78€ Caja. 0,20€ medio trozo. | B47: 3 | C47: =IF(ISNA(VLOOKUP(A47,'Listado de Artículos'!$B$16:$F$1328,5,0)),0,(VLOOKUP(A47,'Listado de Artículos'!$B$16:$F$1328,5,0))) -> 2.9 | D47: 1 | E47: 1 | F47: =IF(D47>0,(E47/D47),"") -> 1 | G47: =IF(D47>0,(100%-F47),"") -> 0 | H47: =IF(B47>0,(G47*B47/F47),"") -> 0 | I47: =IF(B47>0,(B47+H47),"") -> 3 | J47: =IF(C47>0,(C47*I47),"") -> 8.7
A48: Tomate rallado | B48: 0.1 | C48: =IF(ISNA(VLOOKUP(A48,'Listado de Artículos'!$B$16:$F$1328,5,0)),0,(VLOOKUP(A48,'Listado de Artículos'!$B$16:$F$1328,5,0))) -> 1.85 | D48: 1 | E48: 1 | F48: =IF(D48>0,(E48/D48),"") -> 1 | G48: =IF(D48>0,(100%-F48),"") -> 0 | H48: =IF(B48>0,(G48*B48/F48),"") -> 0 | I48: =IF(B48>0,(B48+H48),"") -> 0.1 | J48: =IF(C48>0,(C48*I48),"") -> 0.185
B51: ARTÍCULO | C51: Fingers pollo
B52: TAPA | C52: ELABORADOS | G52: PRECIO DE VENTA P.V.P
B53: unid. | C53: 1 | D53: Coste TOTAL | F53: =SUM(J56:J59) -> 1.1475 | G53: Coste UNID: | I53: =F53/C53 -> 1.1475
A55: ARTICULO | B55: KG | C55: €/UN | D55: BRUTO | E55: NETO | F55: %NETO | G55: %DESP | H55: DESP | I55: SUCIO | J55: € / RACION
A56: Finger solomillo pollo rebozado. caja de 4 kg. 45,19€ | B56: 0.15 | C56: =IF(ISNA(VLOOKUP(A56,'Listado de Artículos'!$B$16:$F$1328,5,0)),0,(VLOOKUP(A56,'Listado de Artículos'!$B$16:$F$1328,5,0))) -> 6.25 | D56: 1 | E56: 1 | F56: =IF(D56>0,(E56/D56),"") -> 1 | G56: =IF(D56>0,(100%-F56),"") -> 0 | H56: =IF(B56>0,(G56*B56/F56),"") -> 0 | I56: =IF(B56>0,(B56+H56),"") -> 0.15 | J56: =IF(C56>0,(C56*I56),"") -> 0.9375
A57: Mayonesa. bote 750 ml. MAKRO. | B57: 0.2 | C57: =IF(ISNA(VLOOKUP(A57,'Listado de Artículos'!$B$16:$F$1328,5,0)),0,(VLOOKUP(A57,'Listado de Artículos'!$B$16:$F$1328,5,0))) -> 1.05 | D57: 1 | E57: 1 | F57: =IF(D57>0,(E57/D57),"") -> 1 | G57: =IF(D57>0,(100%-F57),"") -> 0 | H57: =IF(B57>0,(G57*B57/F57),"") -> 0 | I57: =IF(B57>0,(B57+H57),"") -> 0.2 | J57: =IF(C57>0,(C57*I57),"") -> 0.21
B58: 0.04 | C58: =IF(ISNA(VLOOKUP(A58,'Listado de Artículos'!$B$16:$F$1328,5,0)),0,(VLOOKUP(A58,'Listado de Artículos'!$B$16:$F$1328,5,0))) -> 0 | D58: 1 | E58: 1 | F58: =IF(D58>0,(E58/D58),"") -> 1 | G58: =IF(D58>0,(100%-F58),"") -> 0 | H58: =IF(B58>0,(G58*B58/F58),"") -> 0 | I58: =IF(B58>0,(B58+H58),"") -> 0.04 | J58: =IF(C58>0,(C58*I58),"")
...

Sheet MP boda 31-1
B3: Boda 31-1
B4: FICHA TÉCNICA PLATO
B7: ARTÍCULO | C7: Ceviche de corvina
B8: TAPA | C8: ELABORADOS | G8: PRECIO DE VENTA P.V.P
B9: unid. | C9: 58 | D9: Coste TOTAL | F9: =SUM(J12:J18) -> 34.4878 | G9: Coste UNID: | I9: =F9/C9 -> 0.59461724
A11: ARTICULO | B11: KG | C11: €/UN | D11: BRUTO | E11: NETO | F11: %NETO | G11: %DESP | H11: DESP | I11: SUCIO | J11: € / RACION
A12: Corvina fileteada | B12: 7 | C12: =IF(ISNA(VLOOKUP(A12,'Listado de Artículos'!$B$16:$F$1328,5,0)),0,(VLOOKUP(A12,'Listado de Artículos'!$B$16:$F$1328,5,0))) -> 3.2 | D12: 1 | E12: 1 | F12: =IF(D12>0,(E12/D12),"") -> 1 | G12: =IF(D12>0,(100%-F12),"") -> 0 | H12: =IF(B12>0,(G12*B12/F12),"") -> 0 | I12: =IF(B12>0,(B12+H12),"") -> 7 | J12: =IF(C12>0,(C12*I12),"") -> 22.4
A13: Limones extra. | B13: 2 | C13: =IF(ISNA(VLOOKUP(A13,'Listado de Artículos'!$B$16:$F$1328,5,0)),0,(VLOOKUP(A13,'Listado de Artículos'!$B$16:$F$1328,5,0))) -> 1.38 | D13: 1 | E13: 1 | F13: =IF(D13>0,(E13/D13),"") -> 1 | G13: =IF(D13>0,(100%-F13),"") -> 0 | H13: =IF(B13>0,(G13*B13/F13),"") -> 0 | I13: =IF(B13>0,(B13+H13),"") -> 2 | J13: =IF(C13>0,(C13*I13),"") -> 2.76
A14: Cebolla morada. | B14: 1 | C14: =IF(ISNA(VLOOKUP(A14,'Listado de Artículos'!$B$16:$F$1328,5,0)),0,(VLOOKUP(A14,'Listado de Artículos'!$B$16:$F$1328,5,0))) -> 4.85 | D14: 1 | E14: 1 | F14: =IF(D14>0,(E14/D14),"") -> 1 | G14: =IF(D14>0,(100%-F14),"") -> 0 | H14: =IF(B14>0,(G14*B14/F14),"") -> 0 | I14: =IF(B14>0,(B14+H14),"") -> 1 | J14: =IF(C14>0,(C14*I14),"") -> 4.85
A15: Ají limo | B15: 0.5 | C15: =IF(ISNA(VLOOKUP(A15,'Listado de Artículos'!$B$16:$F$1328,5,0)),0,(VLOOKUP(A15,'Listado de Artículos'!$B$16:$F$1328,5,0))) -> 6 | D15: 1 | E15: 1 | F15: =IF(D15>0,(E15/D15),"") -> 1 | G15: =IF(D15>0,(100%-F15),"") -> 0 | H15: =IF(B15>0,(G15*B15/F15),"") -> 0 | I15: =IF(B15>0,(B15+H15),"") -> 0.5 | J15: =IF(C15>0,(C15*I15),"") -> 3
A16: Cilantro | B16: 0.2 | C16: =IF(ISNA(VLOOKUP(A16,'Listado de Artículos'!$B$16:$F$1328,5,0)),0,(VLOOKUP(A16,'Listado de Artículos'!$B$16:$F$1328,5,0))) -> 0.55 | D16: 1 | E16: 1 | F16: =IF(D16>0,(E16/D16),"") -> 1 | G16: =IF(D16>0,(100%-F16),"") -> 0 | H16: =IF(B16>0,(G16*B16/F16),"") -> 0 | I16: =IF(B16>0,(B16+H16),"") -> 0.2 | J16: =IF(C16>0,(C16*I16),"") -> 0.11
A17: Ajo rojo pelado. pqt 1 kg. | B17: 0.02 | C17: =IF(ISNA(VLOOKUP(A17,'Listado de Artículos'!$B$16:$F$1328,5,0)),0,(VLOOKUP(A17,'Listado de Artículos'!$B$16:$F$1328,5,0))) -> 28.59 | D17: 1 | E17: 1 | F17: =IF(D17>0,(E17/D17),"") -> 1 | G17: =IF(D17>0,(100%-F17),"") -> 0 | H17: =IF(B17>0,(G17*B17/F17),"") -> 0 | I17: =IF(B17>0,(B17+H17),"") -> 0.02 | J17: =IF(C17>0,(C17*I17),"") -> 0.5718
A18: Jenjibre bandeja de 500 gr. | B18: 0.2 | C18: =IF(ISNA(VLOOKUP(A18,'Listado de Artículos'!$B$16:$F$1328,5,0)),0,(VLOOKUP(A18,'Listado de Artículos'!$B$16:$F$1328,5,0))) -> 3.98 | D18: 1 | E18: 1 | F18: =IF(D18>0,(E18/D18),"") -> 1 | G18: =IF(D18>0,(100%-F18),"") -> 0 | H18: =IF(B18>0,(G18*B18/F18),"") -> 0 | I18: =IF(B18>0,(B18+H18),"") -> 0.2 | J18: =IF(C18>0,(C18*I18),"") -> 0.796
B22: ARTÍCULO | C22: Taco de carrillera
B23: TAPA | C23: ELABORADOS | G23: PRECIO DE VENTA P.V.P
B24: unid. | C24: 58 | D24: Coste TOTAL | F24: =SUM(J27:J37) -> 1739.934 | G24: Coste UNID: | I24: =F24/C24 -> 29.998862
A26: ARTICULO | B26: KG | C26: €/UN | D26: BRUTO | E26: NETO | F26: %NETO | G26: %DESP | H26: DESP | I26: SUCIO | J26: € / RACION
A27: Galtes porc | B27: 9 | C27: =IF(ISNA(VLOOKUP(A27,'Listado de Artículos'!$B$16:$F$1328,5,0)),0,(VLOOKUP(A27,'Listado de Artículos'!$B$16:$F$1328,5,0))) -> 5.35 | D27: 1 | E27: 1 | F27: =IF(D27>0,(E27/D27),"") -> 1 | G27: =IF(D27>0,(100%-F27),"") -> 0 | H27: =IF(B27>0,(G27*B27/F27),"") -> 0 | I27: =IF(B27>0,(B27+H27),"") -> 9 | J27: =IF(C27>0,(C27*I27),"") -> 48.15
A28: Ajo rojo pelado. pqt 1 kg. | B28: 0.1 | C28: =IF(ISNA(VLOOKUP(A28,'Listado de Artículos'!$B$16:$F$1328,5,0)),0,(VLOOKUP(A28,'Listado de Artículos'!$B$16:$F$1328,5,0))) -> 28.59 | D28: 1 | E28: 1 | F28: =IF(D28>0,(E28/D28),"") -> 1 | G28: =IF(D28>0,(100%-F28),"") -> 0 | H28: =IF(B28>0,(G28*B28/F28),"") -> 0 | I28: =IF(B28>0,(B28+H28),"") -> 0.1 | J28: =IF(C28>0,(C28*I28),"") -> 2.859
A29: Cebolla blanca. | B29: 1 | C29: =IF(ISNA(VLOOKUP(A29,'Listado de Artículos'!$B$16:$F$1328,5,0)),0,(VLOOKUP(A29,'Listado de Artículos'!$B$16:$F$1328,5,0))) -> 4.5 | D29: 1 | E29: 1 | F29: =IF(D29>0,(E29/D29),"") -> 1 | G29: =IF(D29>0,(100%-F29),"") -> 0 | H29: =IF(B29>0,(G29*B29/F29),"") -> 0 | I29: =IF(B29>0,(B29+H29),"") -> 1 | J29: =IF(C29>0,(C29*I29),"") -> 4.5
A30: Zanahorias. | B30: 0.14 | C30: =IF(ISNA(VLOOKUP(A30,'Listado de Artículos'!$B$16:$F$1328,5,0)),0,(VLOOKUP(A30,'Listado de Artículos'!$B$16:$F$1328,5,0))) -> 4.25 | D30: 1 | E30: 1 | F30: =IF(D30>0,(E30/D30),"") -> 1 | G30: =IF(D30>0,(100%-F30),"") -> 0 | H30: =IF(B30>0,(G30*B30/F30),"") -> 0 | I30: =IF(B30>0,(B30+H30),"") -> 0.14 | J30: =IF(C30>0,(C30*I30),"") -> 0.595
A31: Puerro limpio. | B31: 0.3 | C31: =IF(ISNA(VLOOKUP(A31,'Listado de Artículos'!$B$16:$F$1328,5,0)),0,(VLOOKUP(A31,'Listado de Artículos'!$B$16:$F$1328,5,0))) -> 19.9 | D31: 1 | E31: 1 | F31: =IF(D31>0,(E31/D31),"") -> 1 | G31: =IF(D31>0,(100%-F31),"") -> 0 | H31: =IF(B31>0,(G31*B31/F31),"") -> 0 | I31: =IF(B31>0,(B31+H31),"") -> 0.3 | J31: =IF(C31>0,(C31*I31),"") -> 5.97
A32: Mayonesa 2,2kg | B32: 0.25 | C32: =IF(ISNA(VLOOKUP(A32,'Listado de Artículos'!$B$16:$F$1328,5,0)),0,(VLOOKUP(A32,'Listado de Artículos'!$B$16:$F$1328,5,0))) -> 16.72 | D32: 1 | E32: 1 | F32: =IF(D32>0,(E32/D32),"") -> 1 | G32: =IF(D32>0,(100%-F32),"") -> 0 | H32: =IF(B32>0,(G32*B32/F32),"") -> 0 | I32: =IF(B32>0,(B32+H32),"") -> 0.25 | J32: =IF(C32>0,(C32*I32),"") -> 4.18
A33: Pico de gallo | B33: 1 | C33: =IF(ISNA(VLOOKUP(A33,'Listado de Artículos'!$B$16:$F$1328,5,0)),0,(VLOOKUP(A33,'Listado de Artículos'!$B$16:$F$1328,5,0))) -> 6.75 | D33: 1 | E33: 1 | F33: =IF(D33>0,(E33/D33),"") -> 1 | G33: =IF(D33>0,(100%-F33),"") -> 0 | H33: =IF(B33>0,(G33*B33/F33),"") -> 0 | I33: =IF(B33>0,(B33+H33),"") -> 1 | J33: =IF(C33>0,(C33*I33),"") -> 6.75
A34: Salsa Valentina | B34: 1 | C34: =IF(ISNA(VLOOKUP(A34,'Listado de Artículos'!$B$16:$F$1328,5,0)),0,(VLOOKUP(A34,'Listado de Artículos'!$B$16:$F$1328,5,0))) -> 1660 | D34: 1 | E34: 1 | F34: =IF(D34>0,(E34/D34),"") -> 1 | G34: =IF(D34>0,(100%-F34),"") -> 0 | H34: =IF(B34>0,(G34*B34/F34),"") -> 0 | I34: =IF(B34>0,(B34+H34),"") -> 1 | J34: =IF(C34>0,(C34*I34),"") -> 1660
A35: Salsa Verde | B35: 1 | C35: =IF(ISNA(VLOOKUP(A35,'Listado de Artículos'!$B$16:$F$1328,5,0)),0,(VLOOKUP(A35,'Listado de Artículos'!$B$16:$F$1328,5,0))) -> 3.15 | D35: 1 | E35: 1 | F35: =IF(D35>0,(E35/D35),"") -> 1 | G35: =IF(D35>0,(100%-F35),"") -> 0 | H35: =IF(B35>0,(G35*B35/F35),"") -> 0 | I35: =IF(B35>0,(B35+H35),"") -> 1 | J35: =IF(C35>0,(C35*I35),"") -> 3.15
A36: Limones extra. | B36: 1 | C36: =IF(ISNA(VLOOKUP(A36,'Listado de Artículos'!$B$16:$F$1328,5,0)),0,(VLOOKUP(A36,'Listado de Artículos'!$B$16:$F$1328,5,0))) -> 1.38 | D36: 1 | E36: 1 | F36: =IF(D36>0,(E36/D36),"") -> 1 | G36: =IF(D36>0,(100%-F36),"") -> 0 | H36: =IF(B36>0,(G36*B36/F36),"") -> 0 | I36: =IF(B36>0,(B36+H36),"") -> 1 | J36: =IF(C36>0,(C36*I36),"") -> 1.38
A37: Tortillas maiz | B37: 2 | C37: =IF(ISNA(VLOOKUP(A37,'Listado de Artículos'!$B$16:$F$1328,5,0)),0,(VLOOKUP(A37,'Listado de Artículos'!$B$16:$F$1328,5,0))) -> 1.2 | D37: 1 | E37: 1 | F37: =IF(D37>0,(E37/D37),"") -> 1 | G37: =IF(D37>0,(100%-F37),"") -> 0 | H37: =IF(B37>0,(G37*B37/F37),"") -> 0 | I37: =IF(B37>0,(B37+H37),"") -> 2 | J37: =IF(C37>0,(C37*I37),"") -> 2.4
B41: ARTÍCULO | C41: Pico de gallo
B42: TAPA | C42: ELABORADOS | G42: PRECIO DE VENTA P.V.P
B43: unid. | C43: 1 | D43: Coste TOTAL | F43: =SUM(J46:J48) -> 7.775 | G43: Coste UNID: | I43: =F43/C43 -> 7.775
A45: ARTICULO | B45: KG | C45: €/UN | D45: BRUTO | E45: NETO | F45: %NETO | G45: %DESP | H45: DESP | I45: SUCIO | J45: € / RACION
A46: Cebolla blanca. | B46: 1 | C46: =IF(ISNA(VLOOKUP(A46,'Listado de Artículos'!$B$16:$F$1328,5,0)),0,(VLOOKUP(A46,'Listado de Artículos'!$B$16:$F$1328,5,0))) -> 4.5 | D46: 1 | E46: 1 | F46: =IF(D46>0,(E46/D46),"") -> 1 | G46: =IF(D46>0,(100%-F46),"") -> 0 | H46: =IF(B46>0,(G46*B46/F46),"") -> 0 | I46: =IF(B46>0,(B46+H46),"") -> 1 | J46: =IF(C46>0,(C46*I46),"") -> 4.5
A47: Cilantro | B47: 0.5 | C47: =IF(ISNA(VLOOKUP(A47,'Listado de Artículos'!$B$16:$F$1328,5,0)),0,(VLOOKUP(A47,'Listado de Artículos'!$B$16:$F$1328,5,0))) -> 0.55 | D47: 1 | E47: 1 | F47: =IF(D47>0,(E47/D47),"") -> 1 | G47: =IF(D47>0,(100%-F47),"") -> 0 | H47: =IF(B47>0,(G47*B47/F47),"") -> 0 | I47: =IF(B47>0,(B47+H47),"") -> 0.5 | J47: =IF(C47>0,(C47*I47),"") -> 0.275
A48: Tomate Pera. | B48: 2 | C48: =IF(ISNA(VLOOKUP(A48,'Listado de Artículos'!$B$16:$F$1328,5,0)),0,(VLOOKUP(A48,'Listado de Artículos'!$B$16:$F$1328,5,0))) -> 1.5 | D48: 1 | E48: 1 | F48: =IF(D48>0,(E48/D48),"") -> 1 | G48: =IF(D48>0,(100%-F48),"") -> 0 | H48: =IF(B48>0,(G48*B48/F48),"") -> 0 | I48: =IF(B48>0,(B48+H48),"") -> 2 | J48: =IF(C48>0,(C48*I48),"") -> 3
B51: ARTÍCULO | C51: Guacamole i totopos
B52: TAPA | C52: ELABORADOS | G52: PRECIO DE VENTA P.V.P
B53: unid. | C53: 58 | D53: Coste TOTAL | F53: =SUM(J56:J59) -> 48.55 | G53: Coste UNID: | I53: =F53/C53 -> 0.83706897
A55: ARTICULO | B55: KG | C55: €/UN | D55: BRUTO | E55: NETO | F55: %NETO | G55: %DESP | H55: DESP | I55: SUCIO | J55: € / RACION
A56: Aguacate | B56: 8 | C56: =IF(ISNA(VLOOKUP(A56,'Listado de Artículos'!$B$16:$F$1328,5,0)),0,(VLOOKUP(A56,'Listado de Artículos'!$B$16:$F$1328,5,0))) -> 5.65 | D56: 1 | E56: 1 | F56: =IF(D56>0,(E56/D56),"") -> 1 | G56: =IF(D56>0,(100%-F56),"") -> 0 | H56: =IF(B56>0,(G56*B56/F56),"") -> 0 | I56: =IF(B56>0,(B56+H56),"") -> 8 | J56: =IF(C56>0,(C56*I56),"") -> 45.2
...

Sheet MENU BODA 31-1
A2: MENU BODA
A4: APERITIVO. | B4: P.V.P | C4: NETO | D4: COSTO | E4: FOOD COST
A5: COCTEL BIENVENIDA EN LA PLAZA 1 HORA | B5: GR O KG. | C5: PRECIO KG | D5: EUROS/RACION.
A6: Ceviche de corvina | B6: 1 | C6: =IF(ISNA(VLOOKUP(A6,'Listado de Artículos'!$B$16:$F$1328,5,0)),0,(VLOOKUP(A6,'Listado de Artículos'!$B$16:$F$1328,5,0))) -> 0.59461724 | D6: =B6*C6 -> 0.59461724
A7: Taco de Carrillera porc | B7: 1 | C7: =IF(ISNA(VLOOKUP(A7,'Listado de Artículos'!$B$16:$F$1328,5,0)),0,(VLOOKUP(A7,'Listado de Artículos'!$B$16:$F$1328,5,0))) -> 29.998862 | D7: =B7*C7 -> 29.998862
A8: Guacamole y totopos | B8: 1 | C8: =IF(ISNA(VLOOKUP(A8,'Listado de Artículos'!$B$16:$F$1328,5,0)),0,(VLOOKUP(A8,'Listado de Artículos'!$B$16:$F$1328,5,0))) -> 0.83706897 | D8: =B8*C8 -> 0.83706897
A9: Brocheta langostino | B9: 1 | C9: =IF(ISNA(VLOOKUP(A9,'Listado de Artículos'!$B$16:$F$1328,5,0)),0,(VLOOKUP(A9,'Listado de Artículos'!$B$16:$F$1328,5,0))) -> 0.75613793 | D9: =B9*C9 -> 0.75613793
A10: Pan de cristal con jamón | B10: 1 | C10: =IF(ISNA(VLOOKUP(A10,'Listado de Artículos'!$B$16:$F$1328,5,0)),0,(VLOOKUP(A10,'Listado de Artículos'!$B$16:$F$1328,5,0))) -> 3.1085 | D10: =B10*C10 -> 3.1085
A11: Tabla de quesos | B11: 1 | C11: =IF(ISNA(VLOOKUP(A11,'Listado de Artículos'!$B$16:$F$1328,5,0)),0,(VLOOKUP(A11,'Listado de Artículos'!$B$16:$F$1328,5,0))) -> 0.15748276 | D11: =B11*C11 -> 0.15748276
A12: Agua de jamaica | B12: 1 | C12: =IF(ISNA(VLOOKUP(A12,'Listado de Artículos'!$B$16:$F$1328,5,0)),0,(VLOOKUP(A12,'Listado de Artículos'!$B$16:$F$1328,5,0))) -> 0.1256 | D12: =B12*C12 -> 0.1256
A13: Agua de limón | B13: 1 | C13: =IF(ISNA(VLOOKUP(A13,'Listado de Artículos'!$B$16:$F$1328,5,0)),0,(VLOOKUP(A13,'Listado de Artículos'!$B$16:$F$1328,5,0))) -> 0.13982759 | D13: =B13*C13 -> 0.13982759
A14: Entrante
A15: Crema calenta tomàquet | B15: 1 | C15: =IF(ISNA(VLOOKUP(A15,'Listado de Artículos'!$B$16:$F$1328,5,0)),0,(VLOOKUP(A15,'Listado de Artículos'!$B$16:$F$1328,5,0))) -> 1.7559914 | D15: =B15*C15 -> 1.7559914
A16: PRIMERO.
A17: Flor de alcachofa con jamón | B17: 1 | C17: =IF(ISNA(VLOOKUP(A17,'Listado de Artículos'!$B$16:$F$1328,5,0)),0,(VLOOKUP(A17,'Listado de Artículos'!$B$16:$F$1328,5,0))) -> 0.39396552 | D17: =B17*C17 -> 0.39396552
A18: SEGUNDO
